Workbook
Name DinhLuong: '[1] Chi tiết SL '!$O$8:$O$8001
Name NgaySX: '[1] Chi tiết SL '!$C$8:$C$8001
Name TongKho: '[1] Chi tiết SL '!$N$8:$N$8001
Name TrongLuong: '[1] Chi tiết SL '!$AP$8:$AP$8001

Sheet 5.26
B1: DATA CẦN NHẬP HÀNG THÁNG
B2: lưu ý : chỉ nhập các ô trắng | G2: THÁNG 5.2026
D3: NGÀY | F3: Tổng | G3: 1 | H3: 2 | I3: 3 | J3: 4 | K3: 5 | L3: 6 | M3: 7 | N3: 8 | O3: 9 | P3: 10 | Q3: 11 | R3: 12 | S3: 13 | T3: 14 | U3: 15 | V3: 16 | W3: 17 | X3: 18 | Y3: 19 | Z3: 20 | AA3: 21 | AB3: 22 | AC3: 23 | AD3: 24 | AE3: 25 | AF3: 26 | AG3: 27 | AH3: 28 | AI3: 29 | AJ3: 30 | AK3: 31
B4: Số ngày sản xuất | D4: Tổng số ngày sản xuất | E4: Ngày | F4: =SUM(G4:AL4) -> 30 | G4: 1 | H4: 1 | I4: 1 | J4: 1 | K4: 1 | L4: 1 | M4: 1 | N4: 1 | O4: 1 | P4: 1 | Q4: 1 | R4: 1 | T4: 1 | U4: 1 | V4: 1 | W4: 1 | X4: 1 | Y4: 1 | Z4: 1 | AA4: 1 | AB4: 1 | AC4: 1 | AD4: 1 | AE4: 1 | AF4: 1 | AG4: 1 | AH4: 1 | AI4: 1 | AJ4: 1 | AK4: 1
D5: Tổng Số ngày sx giấy mặt | E5: Ngày | F5: =SUM(G5:AL5) -> 30 | G5: 1 | H5: 1 | I5: 1 | J5: 1 | K5: 1 | L5: 1 | M5: 1 | N5: 1 | O5: 1 | P5: 1 | Q5: 1 | R5: 1 | T5: 1 | U5: 1 | V5: 1 | W5: 1 | X5: 1 | Y5: 1 | Z5: 1 | AA5: 1 | AB5: 1 | AC5: 1 | AD5: 1 | AE5: 1 | AF5: 1 | AG5: 1 | AH5: 1 | AI5: 1 | AJ5: 1 | AK5: 1
D6: Tổng Số ngày sx Kraftlinet | E6: Ngày | F6: =SUM(G6:AL6) -> 3 | G6: 0 | H6: 0 | I6: 0 | J6: 0 | K6: 0 | L6: 0 | M6: 0 | N6: 0 | O6: 0 | P6: 0 | Q6: 0 | R6: 0 | T6: 0 | U6: 0 | V6: 0 | W6: 0 | X6: 0 | Y6: 0 | Z6: 0 | AA6: 0 | AB6: 0 | AC6: 0 | AD6: 0 | AE6: 0 | AF6: 0 | AG6: 0 | AH6: 0 | AI6: 1 | AJ6: 1 | AK6: 1
B7: KẾ HOẠCH | C7: Sản lượng KH | D7: Giấy sóng-KH | E7: Tấn | F7: =SUM(G7:AL7) -> 1040 | G7: 250 | H7: 70 | I7: 10 | R7: 200 | T7: 110 | V7: 150 | AG7: 50 | AH7: 165 | AI7: 35
D8: Giấy mặt-KH | E8: Tấn | F8: =SUM(G8:AL8) -> 11835 | G8: 100 | H8: 350 | I8: 470 | J8: 490 | K8: 500 | L8: 520 | M8: 490 | N8: 450 | O8: 510 | P8: 450 | Q8: 480 | R8: 100 | T8: 280 | U8: 500 | V8: 150 | W8: 510 | X8: 500 | Y8: 460 | Z8: 500 | AA8: 510 | AB8: 500 | AC8: 530 | AD8: 540 | AE8: 530 | AF8: 480 | AG8: 450 | AH8: 165 | AI8: 320
D9: Kraftlinet-KH | E9: Tấn | F9: =SUM(G9:AL9) -> 1125 | AI9: 125 | AJ9: 500 | AK9: 500
D10: TỔNG SL KẾ HOẠCH | E10: Tấn | F10: =SUM(G10:AL10) -> 14000 | G10: =+SUM(G7:G9) -> 350 | H10: =+SUM(H7:H9) -> 420 | I10: =+SUM(I7:I9) -> 480 | J10: =+SUM(J7:J9) -> 490 | K10: =+SUM(K7:K9) -> 500 | L10: =+SUM(L7:L9) -> 520 | M10: =+SUM(M7:M9) -> 490 | N10: =+SUM(N7:N9) -> 450 | ... AK10: =+SUM(AK7:AK9) -> 500 | AL10: =AL7+AL9+AL8 -> 0
B11: THỰC TẾ | C11: SL Thực tế | D11: Giấy sóng-TT | E11: Tấn | F11: =SUM(G11:AL11) -> 941.502 | G11: 225.113 | H11: 70.328 | I11: 9.524 | R11: 163.883 | T11: 88.073 | V11: 148.262 | AG11: 46.447 | AH11: 155.031 | AI11: 34.841
D12: Giấy mặt-TT | E12: Tấn | F12: =SUM(G12:AL12) -> 11145.36 | G12: 87.175 | H12: 333.601 | I12: 399.904 | J12: 452.126 | K12: 507.525 | L12: 516.427 | M12: 491.105 | N12: 435.798 | O12: 489.232 | P12: 437.576 | Q12: 416.223 | R12: 89.94 | T12: 182.204 | U12: 481.734 | V12: 137.877 | W12: 473.309 | X12: 473.169 | Y12: 453.907 | Z12: 494.699 | AA12: 484.961 | AB12: 426.851 | AC12: 510.075 | AD12: 525.928 | AE12: 517.883 | AF12: 437.34 | AG12: 434.61 | AH12: 160.497 | AI12: 293.684
D13: Kraftlinet-TT | E13: Tấn | F13: =SUM(G13:AL13) -> 1032.408 | AI13: 119.193 | AJ13: 484.541 | AK13: 428.674
D14: TỔNG SL THƯC TẾ | E14: Tấn | F14: =SUM(G14:AL14) -> 13119.27 | G14: =+SUM(G11:G13) -> 312.288 | H14: =+SUM(H11:H13) -> 403.929 | I14: =+SUM(I11:I13) -> 409.428 | J14: =+SUM(J11:J13) -> 452.126 | K14: =+SUM(K11:K13) -> 507.525 | L14: =+SUM(L11:L13) -> 516.427 | M14: =+SUM(M11:M13) -> 491.105 | N14: =+SUM(N11:N13) -> 435.798 | ... AK14: =+SUM(AK11:AK13) -> 428.674 | AL14: =AL11+AL12+AL13 -> 0
B15: Chênh lệch | C15: +, - | D15: GIẤY SÓNG | E15: Tấn | F15: =SUM(G15:AL15) -> -98.498 | G15: =G11-G7 -> -24.887 | H15: =H11-H7 -> 0.328 | I15: =I11-I7 -> -0.476 | J15: =J11-J7 -> 0 | K15: =K11-K7 -> 0 | L15: =L11-L7 -> 0 | M15: =M11-M7 -> 0 | N15: =N11-N7 -> 0 | ... AL15: =AL11-AL7 -> 0
D16: GIẤY MẶT | E16: Tấn | F16: =SUM(G16:AL16) -> -689.64 | G16: =G12-G8 -> -12.825 | H16: =H12-H8 -> -16.399 | I16: =I12-I8 -> -70.096 | J16: =J12-J8 -> -37.874 | K16: =K12-K8 -> 7.525 | L16: =L12-L8 -> -3.573 | M16: =M12-M8 -> 1.105 | N16: =N12-N8 -> -14.202 | ... AL16: =AL12-AL8 -> 0
D17: Kraftlinet | E17: Tấn | F17: =SUM(G17:AL17) -> -92.592 | G17: =G13-G9 -> 0 | H17: =H13-H9 -> 0 | I17: =I13-I9 -> 0 | J17: =J13-J9 -> 0 | K17: =K13-K9 -> 0 | L17: =L13-L9 -> 0 | M17: =M13-M9 -> 0 | N17: =N13-N9 -> 0 | ... AL17: =AL13-AL9 -> 0
D18: TỔNG CHÊNH | E18: Tấn | F18: =SUM(G18:AL18) -> -880.73 | G18: =G16+G15+G17 -> -37.712 | H18: =H16+H15+H17 -> -16.071 | I18: =I16+I15+I17 -> -70.572 | J18: =J16+J15+J17 -> -37.874 | K18: =K16+K15+K17 -> 7.525 | L18: =L16+L15+L17 -> -3.573 | M18: =M16+M15+M17 -> 1.105 | N18: =N16+N15+N17 -> -14.202 | ... AL18: =AL16+AL15+AL17 -> 0
B19: Các hang mục liên quan đến | C19: Dừng bất thường | D19: Dừng bất thường đứt giấy | E19: Lần | F19: =SUM(G19:AL19) -> 41 | G19: 1 | H19: 3 | O19: 1 | R19: 1 | T19: 5 | U19: 5 | V19: 3 | W19: 2 | X19: 4 | Y19: 4 | Z19: 3 | AA19: 1 | AG19: 1 | AH19: 2 | AI19: 5
E20: Tấn tp | F20: =SUM(G20:AL20) -> 190 | G20: 8 | H20: 16 | O20: 5 | R20: 6 | T20: 15 | U20: 18 | V20: 14 | W20: 10 | X20: 17 | Y20: 6 | Z20: 5 | AA20: 5 | AG20: 19 | AH20: 14 | AI20: 32
D21: Dừng bất thường khác | E21: Lần | F21: =SUM(G21:AL21) -> 10 | I21: 2 | J21: 1 | Q21: 1 | R21: 1 | W21: 1 | X21: 1 | AB21: 1 | AF21: 1 | AK21: 1
E22: Tấn tp | F22: =SUM(G22:AL22) -> 323 | I22: 50 | J22: 20 | Q22: 54 | R22: 10 | W22: 10 | X22: 10 | AB22: 55 | AF22: 43 | AK22: 71
C23: Dừng kế hoạch | D23: Dừng kế hoạch NHƯNG LÀ KH PHÁT SINH | E23: Lần | F23: =SUM(G23:AL23) -> 2 | G23: 1 | T23: 1
E24: Tấn tp | F24: =SUM(G24:AL24) -> 100 | G24: 20 | T24: 80
C25: Khác | D25: Giảm tốc độ so với kế hoạch | E25: Lần | F25: =SUM(G25:AL25) -> 15 | G25: 1 | I25: 1 | J25: 1 | N25: 1 | O25: 1 | P25: 1 | Q25: 1 | R25: 1 | T25: 1 | W25: 1 | AA25: 1 | AB25: 1 | AC25: 1 | AD25: 1 | AE25: 1
E26: Tấn tp | F26: =SUM(G26:AL26) -> 257 | G26: 10 | I26: 21 | J26: 18 | N26: 14 | O26: 16 | P26: 12 | Q26: 10 | R26: 30 | T26: 25 | W26: 17 | AA26: 20 | AB26: =73-55 -> 18 | AC26: 20 | AD26: 14 | AE26: 12
C27: Sự cố chất lượng | D27: Hủy hàng do lỗi chất lượng | E27: Lần | F27: =SUM(G27:AL27) -> 0
E28: Tấn tp | F28: =SUM(G28:AL28) -> 0
C29: TỔNG ẢNH HƯỞNG | E29: Lần | F29: =SUM(G29:AL29) -> 68 | G29: =G19+G21+G23+G25+G27 -> 3 | H29: =H19+H21+H23+H25+H27 -> 3 | I29: =I19+I21+I23+I25+I27 -> 3 | J29: =J19+J21+J23+J25+J27 -> 2 | K29: =K19+K21+K23+K25+K27 -> 0 | L29: =L19+L21+L23+L25+L27 -> 0 | M29: =M19+M21+M23+M25+M27 -> 0 | N29: =N19+N21+N23+N25+N27 -> 1 | ... AL29: =AL19+AL21+AL23+AL25+AL27 -> 0 | AN29: =SUM(AB10:AH10) -> 3410
E30: Tấn tp | F30: =SUM(G30:AL30) -> 870 | G30: =G20+G22+G24+G26+G28 -> 38 | H30: =H20+H22+H24+H26+H28 -> 16 | I30: =I20+I22+I24+I26+I28 -> 71 | J30: =J20+J22+J24+J26+J28 -> 38 | K30: =K20+K22+K24+K26+K28 -> 0 | L30: =L20+L22+L24+L26+L28 -> 0 | M30: =M20+M22+M24+M26+M28 -> 0 | N30: =N20+N22+N24+N26+N28 -> 14 | ... AL30: =AL20+AL22+AL24+AL26+AL28 -> 0 | AN30: =SUM(AB14:AH14) -> 3214.662

Sheet Data NĂM
B2: SL Năm | F2: 2021 | G2: 2022 | H2: 2023 | I2: 2024 | J2: 2025 | K2: 2026 | L2: 2021 | T2: 2022 | AF2: 2023 | AR2: 2024 | BJ2: 2025 | BP2: 2026
L3: Tháng 5 | M3: Tháng 6 | N3: Tháng 7 | O3: Tháng 8 | P3: Tháng 9 | Q3: Tháng 10 | R3: Tháng 11 | S3: Tháng 12 | T3: Tháng 1 | U3: Tháng 2 | V3: Tháng 3 | W3: Tháng 4 | X3: Tháng 5 | Y3: Tháng 6 | Z3: Tháng 7 | AA3: Tháng 8 | AB3: Tháng 9 | AC3: Tháng 10 | AD3: Tháng 11 | AE3: Tháng 12 | AF3: Tháng 1 | AG3: Tháng 2 | AH3: Tháng 3 | AI3: Tháng 4 | AJ3: Tháng 5 | AK3: Tháng 6 | AL3: Tháng 7 | AM3: Tháng 8 | AN3: Tháng 9 | AO3: Tháng 10 | AP3: Tháng 11 | AQ3: Tháng 12 | AR3: Tháng 1 | AS3: Tháng 2 | AT3: Tháng 3 | AU3: Tháng 4 | AV3: Tháng 5 | AW3: Tháng 6 | AX3: Tháng 7 | AY3: Tháng 8 | AZ3: Tháng 9 | BA3: Tháng 10 | BB3: Tháng 11 | BC3: Tháng 12 | BD3: Tháng 1 | BE3: Tháng 2 | BF3: Tháng 3 | BG3: Tháng 4 | BH3: Tháng 5 | BI3: Tháng 6 | BJ3: Tháng 7 | BK3: Tháng 8 | BL3: Tháng 9 | BM3: Tháng 10 | BN3: Tháng 11 | BO3: Tháng 12 | BP3: Tháng 1 | BQ3: Tháng 2 | BR3: Tháng 3 | BS3: Tháng 4 | BT3: Tháng 5
B4: Số ngày sản xuất | D4: Tổng Số ngày đã SX | E4: Ngày | F4: =+SUM(L4:S4) -> 225 | G4: =+SUM(T4:AE4) -> 342 | H4: =+SUM(AF4:AQ4) -> 356 | I4: =+SUM(AR4:BC4) -> 326 | J4: =+SUM(BD4:BT4) -> 492 | L4: 21 | M4: 28 | N4: 31 | O4: 29 | P4: 28 | Q4: 30 | R4: 29 | S4: 29 | T4: 28 | U4: 23 | V4: 30 | W4: 30 | X4: 31 | Y4: 28 | Z4: 31 | AA4: 29 | AB4: 25 | AC4: 29 | AD4: 30 | AE4: 28 | AF4: 25 | AG4: 28 | AH4: 31 | AI4: 27 | AJ4: 31 | AK4: 30 | AL4: 31 | AM4: 31 | AN4: 30 | AO4: 31 | AP4: 30 | AQ4: 31 | AR4: 28 | AS4: 25 | AT4: 30 | AU4: 23 | AV4: 28 | AW4: 26 | AX4: 30 | AY4: 25 | AZ4: 26 | BA4: 29 | BB4: 26 | BC4: 30 | BD4: 30 | BE4: 25 | BF4: 29 | BG4: 29 | BH4: 28 | BI4: 29 | BJ4: 30 | BK4: 28 | BL4: 28 | BM4: 31 | BN4: 28 | BO4: 31 | BP4: 30 | BQ4: 27 | BR4: 30 | BS4: 29 | BT4: =+'5.26'!F4 -> 30
D5: Tổng Số ngày sx giấy mặt | E5: Ngày | F5: =+SUM(L5:S5) -> 118 | G5: =+SUM(T5:AE5) -> 311 | H5: =+SUM(AF5:AQ5) -> 324 | I5: =+SUM(AR5:BC5) -> 318 | J5: =+SUM(BD5:BT5) -> 487 | L5: 0 | M5: 5 | N5: 8 | O5: 16 | P5: 19 | Q5: 20 | R5: 25 | S5: 25 | T5: 26 | U5: 20 | V5: 27 | W5: 24 | X5: 30 | Y5: 27 | Z5: 28 | AA5: 28 | AB5: 20 | AC5: 24 | AD5: 29 | AE5: 28 | AF5: 21 | AG5: 27 | AH5: 27 | AI5: 24 | AJ5: 29 | AK5: 26 | AL5: 28 | AM5: 28 | AN5: 28 | AO5: 28 | AP5: 28 | AQ5: 30 | AR5: 28 | AS5: 25 | AT5: 30 | AU5: 23 | AV5: 26 | AW5: 26 | AX5: 30 | AY5: 20 | AZ5: 26 | BA5: 28 | BB5: 26 | BC5: 30 | BD5: 30 | BE5: 25 | BF5: 29 | BG5: 27 | BH5: 28 | BI5: 29 | BJ5: 30 | BK5: 28 | BL5: 28 | BM5: 31 | BN5: 28 | BO5: 29 | BP5: 30 | BQ5: 27 | BR5: 29 | BS5: 29 | BT5: =+'5.26'!F5 -> 30
D6: Tổng Số ngày sx giấy Kraftline | E6: Ngày | F6: =+SUM(L6:S6) -> 0 | G6: =+SUM(T6:AE6) -> 8 | H6: =+SUM(AF6:AQ6) -> 36 | I6: =+SUM(AR6:BC6) -> 79 | J6: =+SUM(BD6:BT6) -> 92 | L6: 0 | Z6: 3 | AA6: 1 | AB6: 1 | AC6: 1 | AE6: 2 | AF6: 0 | AG6: 2 | AH6: 3 | AI6: 3 | AJ6: 3 | AK6: 3 | AL6: 3 | AM6: 4 | AN6: 2 | AO6: 5 | AP6: 3 | AQ6: 5 | AR6: 4 | AS6: 6 | AT6: 6 | AU6: 5 | AV6: 2 | AW6: 8 | AX6: 8 | AY6: 9 | AZ6: 9 | BA6: 7 | BB6: 7 | BC6: 8 | BD6: 9 | BE6: 9 | BF6: 8 | BG6: 5 | BH6: 6 | BI6: 6 | BJ6: 3 | BK6: 6 | BL6: 2 | BM6: 7 | BN6: 4 | BO6: 4 | BP6: 7 | BQ6: 4 | BR6: 4 | BS6: 5 | BT6: =+'5.26'!F6 -> 3
B7: KẾ HOẠCH | C7: Sản lượng KH | D7: Giấy sóng-KH | E7: Tấn | F7: =+SUM(L7:S7) -> 40397.894 | G7: =+SUM(T7:AE7) -> 37100.1 | H7: =+SUM(AF7:AQ7) -> 26535.138 | I7: =+SUM(AR7:BC7) -> 12464.328 | J7: =+SUM(BD7:BO7) -> 16779 | K7: =+SUM(BP7:BU7) -> 5403 | L7: 5397.3271 | M7: 6089.916 | N7: 6895.9187 | O7: 5384.2896 | P7: 4525.799 | Q7: 5291.0806 | R7: 3851.0751 | S7: 2962.4883 | T7: 1825.5344 | U7: 1984.2686 | V7: 3718.9664 | W7: 3791.5025 | X7: 2281.3659 | Y7: 2553.3608 | Z7: 3839.212 | AA7: 3429.4877 | AB7: 4515.5855 | AC7: 3396.5425 | AD7: 3291.564 | AE7: 2472.7094 | AF7: 2987.1446 | AG7: 2524.5948 | AH7: 2879.7475 | AI7: 2157.4501 | AJ7: 1881.0117 | AK7: 2336.3825 | AL7: 1839.9148 | AM7: 2477.9482 | AN7: 2289.9179 | AO7: 1762.574 | AP7: 1832.1197 | AQ7: 1566.332 | AR7: 1322.3167 | AS7: 903.53594 | AT7: 1070.4552 | AU7: 1395.9288 | AV7: 1185.5986 | AW7: 874.07315 | AX7: 1012.5012 | AY7: 352 | AZ7: 741.97261 | BA7: 1454.4112 | BB7: 1311.3067 | BC7: 840.22766 | BD7: 1120 | BE7: 1115 | BF7: 1265 | BG7: 2810 | BH7: 2215 | BI7: 1460 | BJ7: 1385 | BK7: =+'[2]8.25'!F7 -> 1135 | BL7: 1193 | BM7: 1050 | BN7: 1010 | BO7: 1021 | BP7: 1213 | BQ7: 760 | BR7: 770 | BS7: 1620 | BT7: =+'5.26'!F7 -> 1040
D8: Giấy mặt-KH | E8: Tấn | F8: =+SUM(L8:S8) -> 34781.727 | G8: =+SUM(T8:AE8) -> 84192.395 | H8: =+SUM(AF8:AQ8) -> 92552.526 | I8: =+SUM(AR8:BC8) -> 95041.54 | J8: =+SUM(BD8:BO8) -> 121993 | K8: =+SUM(BP8:BU8) -> 54940 | L8: 0 | M8: 1044.7524 | N8: 1913.6222 | O8: 4998.4644 | P8: 5880.219 | Q8: 6206.0604 | R8: 7137.3529 | S8: 7601.2557 | T8: 8485.4811 | U8: 6459.0148 | V8: 7204.1475 | W8: 7160.8645 | X8: 8216.6088 | Y8: 7721.2732 | Z8: 6781.6207 | AA8: 6963.1318 | AB8: 4333.1845 | AC8: 6544.3217 | AD8: 6589.0458 | AE8: 7733.701 | AF8: 5478.3336 | AG8: 6940.1446 | AH8: 7528.5883 | AI8: 6704.2644 | AJ8: 8412.5214 | AK8: 7803.2079 | AL8: 8132.0204 | AM8: 7711.7592 | AN8: 8397.8394 | AO8: 7434.018 | AP8: 8792.4241 | AQ8: 9217.4045 | AR8: 8780.6346 | AS8: 8054.736 | AT8: 9168.4192 | AU8: 5995.6556 | AV8: 7332.7792 | AW8: 8199.8844 | AX8: 7880.5778 | AY8: 6971.5847 | AZ8: 8696.7811 | BA8: 8058.4748 | BB8: 6981.7389 | BC8: 8920.274 | BD8: 9430 | BE8: 8300 | BF8: 9185 | BG8: 7940 | BH8: 8370 | BI8: 9945 | BJ8: 11805 | BK8: =+'[2]8.25'!F8 -> 11120 | BL8: 11647 | BM8: 11814 | BN8: 10765 | BO8: 11672 | BP8: 10800 | BQ8: 10350 | BR8: 11685 | BS8: 10270 | BT8: =+'5.26'!F8 -> 11835
D9: Giấy Kraftline-KH | E9: Tấn | F9: =+SUM(L9:S9) -> 0 | G9: =+SUM(T9:AE9) -> 889.64976 | H9: =+SUM(AF9:AQ9) -> 7941.7685 | I9: =+SUM(AR9:BC9) -> 19805.051 | J9: =+SUM(BD9:BO9) -> 20628 | K9: =+SUM(BP9:BU9) -> 7992 | Z9: 371.94307 | AA9: 105.11907 | AB9: 76.808227 | AC9: 147.88514 | AD9: 0 | AE9: 187.89425 | AF9: 0 | AG9: 401.64335 | AH9: 495.19164 | AI9: 466.42666 | AJ9: 1052.2787 | AK9: 600.47207 | AL9: 666.27805 | AM9: 1137.1339 | AN9: 487.35155 | AO9: 961.53156 | AP9: 687.13763 | AQ9: 986.32343 | AR9: 1356.1745 | AS9: 1710.4514 | AT9: 2201.693 | AU9: 1262.3019 | AV9: 410.7133 | AW9: 1441.8506 | AX9: 1722.921 | AY9: 2358 | AZ9: 1639.1327 | BA9: 2294.1034 | BB9: 1408.2106 | BC9: 1999.4984 | BD9: 2640 | BE9: 3035 | BF9: 2450 | BG9: 1440 | BH9: 1880 | BI9: 1475 | BJ9: 810 | BK9: =+'[2]8.25'!F9 -> 1945 | BL9: 1035 | BM9: 936 | BN9: 1475 | BO9: 1507 | BP9: 2187 | BQ9: 1445 | BR9: 1545 | BS9: 1690 | BT9: =+'5.26'!F9 -> 1125
D10: TỔNG SL KẾ HOẠCH | E10: Tấn | F10: =+SUM(L10:S10) -> 75179.622 | G10: =+SUM(T10:AE10) -> 122182.15 | H10: =+SUM(AF10:AQ10) -> 127029.43 | I10: =+SUM(AR10:BC10) -> 127310.92 | J10: =+SUM(BD10:BO10) -> 159400 | K10: =+SUM(BP10:BU10) -> 68335 | L10: =+SUM(L7:L9) -> 5397.3271 | M10: =+SUM(M7:M9) -> 7134.6685 | N10: =+SUM(N7:N9) -> 8809.5409 | O10: =+SUM(O7:O9) -> 10382.754 | P10: =+SUM(P7:P9) -> 10406.018 | Q10: =+SUM(Q7:Q9) -> 11497.141 | R10: =+SUM(R7:R9) -> 10988.428 | S10: =+SUM(S7:S9) -> 10563.744 | ... AG10: =+SUM(AG7:AG9) -> 9866.3827 | AH10: 10903.527 | AI10: =+SUM(AI7:AI9) -> 9328.1412 | AJ10: =+SUM(AJ7:AJ9) -> 11345.812 | AK10: =+SUM(AK7:AK9) -> 10740.062 | AL10: =+SUM(AL7:AL9) -> 10638.213 | AM10: =+SUM(AM7:AM9) -> 11326.841 | AN10: =+SUM(AN7:AN9) -> 11175.109 | AO10: =+SUM(AO7:AO9) -> 10158.124 | AP10: =+SUM(AP7:AP9) -> 11311.681 | AQ10: =+SUM(AQ7:AQ9) -> 11770.06 | AR10: 11459.126 | AS10: 10668.723 | AT10: 12440.567 | AU10: 8653.8863 | AV10: 8929.0912 | AW10: 10515.808 | AX10: 10616 | AY10: 9681.5847 | AZ10: 11077.886 | BA10: 11806.989 | BB10: 9701.2562 | BC10: 11760 | BD10: =SUM(BD7:BD9) -> 13190 | BE10: =SUM(BE7:BE9) -> 12450 | BF10: =SUM(BF7:BF9) -> 12900 | BG10: =SUM(BG7:BG9) -> 12190 | BH10: =SUM(BH7:BH9) -> 12465 | BI10: =SUM(BI7:BI9) -> 12880 | BJ10: =SUM(BJ7:BJ9) -> 14000 | BK10: =SUM(BK7:BK9) -> 14200 | BL10: =SUM(BL7:BL9) -> 13875 | BM10: 13800 | BN10: 13250 | BO10: 14200 | BP10: 14200 | BQ10: 12555 | BR10: 14000 | BS10: 13580 | BT10: =SUM(BT7:BT9) -> 14000 | BW10: Sản lượng TT | BX10: SL lỗi | BY10: % trên SL từng loại giấy | BZ10: % trên SL tổng
B11: THỰC TẾ | C11: SL Thực tế | D11: Giấy sóng-TT | E11: Tấn | F11: =+SUM(L11:S11) -> 34509.206 | G11: =+SUM(T11:AE11) -> 35531.191 | H11: =+SUM(AF11:AQ11) -> 25275.764 | I11: =+SUM(AR11:BC11) -> 11767.882 | J11: =+SUM(BD11:BO11) -> 15186.893 | K11: =+SUM(BP11:BU11) -> 5053.334 | L11: 2660.578 | M11: 6138.536 | N11: 5926.994 | O11: 4718.127 | P11: 3961.241 | Q11: 4702.041 | R11: 3658.974 | S11: 2742.715 | T11: 1665.45 | U11: 1791.62 | V11: 3532.815 | W11: 3769.148 | X11: 2243.593 | Y11: 2554.483 | Z11: 3652.553 | AA11: 3354.392 | AB11: 4425.471 | AC11: 3254.017 | AD11: 2874.22 | AE11: 2413.429 | AF11: 2859.595 | AG11: 2526.357 | AH11: 2943.589 | AI11: 1980.389 | AJ11: 1828.666 | AK11: 2306.129 | AL11: 1705.349 | AM11: 2395.615 | AN11: 1890.575 | AO11: 1520.172 | AP11: 1809.545 | AQ11: 1509.783 | AR11: 1131.971 | AS11: 867.75 | AT11: 1046.847 | AU11: 1182.97 | AV11: 1159.167 | AW11: 790.09 | AX11: 989.153 | AY11: 346.985 | AZ11: 700.72 | BA11: 1354.907 | BB11: 1165.376 | BC11: 1031.946 | BD11: 1057.855 | BE11: 922.691 | BF11: 1119.671 | BG11: 2385.473 | BH11: 2000.447 | BI11: 1486.528 | BJ11: 1386.195 | BK11: =+'[2]8.25'!F11 -> 1071.066 | BL11: 1175.903 | BM11: 1051.241 | BN11: 617.843 | BO11: 911.98 | BP11: 1002.502 | BQ11: 722.141 | BR11: 732.629 | BS11: 1654.56 | BT11: =+'5.26'!F11 -> 941.502 | BV11: M3 | BW11: 941.502 | BX11: 3.5 | BY11: =BX11/BW11 -> 0.0037174642 | BZ11: =BX11/$BW$14 -> 0.00026678314
D12: Giấy mặt-TT | E12: Tấn | F12: =+SUM(L12:S12) -> 31552.498 | G12: =+SUM(T12:AE12) -> 82586.796 | H12: =+SUM(AF12:AQ12) -> 90749.445 | I12: =+SUM(AR12:BC12) -> 90236.048 | J12: =+SUM(BD12:BO12) -> 113789.6 | K12: =+SUM(BP12:BU12) -> 51853.368 | L12: 0 | M12: 685.756 | N12: 1862.56 | O12: 4625.8 | P12: 5719.33 | Q12: 4981.942 | R12: 6655.45 | S12: 7021.66 | T12: 8102.826 | U12: 6377.805 | V12: 7318.274 | W12: 7043.48 | X12: 8088.479 | Y12: 7818.9562 | Z12: 6679.906 | AA12: 6878.736 | AB12: 4177.499 | AC12: 6206.324 | AD12: 6398.077 | AE12: 7496.434 | AF12: 5469.113 | AG12: 6975.175 | AH12: 7725.229 | AI12: 6390.088 | AJ12: 8147.802 | AK12: 7697.101 | AL12: 7580.94 | AM12: 7834.417 | AN12: 7986.824 | AO12: 7059.142 | AP12: 8709.946 | AQ12: 9173.668 | AR12: 8499.816 | AS12: 7821.389 | AT12: 8769.179 | AU12: 5643.348 | AV12: 7179.899 | AW12: 7797.846 | AX12: 7160.428 | AY12: 6829.12 | AZ12: 8743.874 | BA12: 7735.586 | BB12: 6369.097 | BC12: 7686.466 | BD12: 9048.104 | BE12: 7287.768 | BF12: 7852.897 | BG12: 7121.736 | BH12: 8084.058 | BI12: 9267.642 | BJ12: 11333.927 | BK12: =+'[2]8.25'!F12 -> 10112.45 | BL12: 10511.95 | BM12: 11246.421 | BN12: 10130.658 | BO12: 11791.994 | BP12: 10011.423 | BQ12: 9960.315 | BR12: 11050.316 | BS12: 9685.954 | BT12: =+'5.26'!F12 -> 11145.36 | BV12: T3 | BW12: 11145.36 | BX12: 177.775 | BY12: =BX12/BW12 -> 0.015950584 | BZ12: =BX12/$BW$14 -> 0.013550678
D13: Giấy Kraftline-TT | E13: Tấn | F13: =+SUM(L13:S13) -> 0 | G13: =+SUM(T13:AE13) -> 847.149 | H13: =+SUM(AF13:AQ13) -> 7819.05 | I13: =+SUM(AR13:BC13) -> 18734.028 | J13: =+SUM(BD13:BO13) -> 19060.961 | K13: =+SUM(BP13:BU13) -> 7749.82 | Z13: 338.111 | AA13: 106.197 | AB13: 75.115 | AC13: 142.123 | AD13: 0 | AE13: 185.603 | AF13: 0 | AG13: 384.654 | AH13: 473.896 | AI13: 480.163 | AJ13: 1058.319 | AK13: 582.176 | AL13: 658.204 | AM13: 1086.758 | AN13: 470.972 | AO13: 968.706 | AP13: 674.029 | AQ13: 981.173 | AR13: 1317.871 | AS13: 1716.339 | AT13: 2199.41 | AU13: 1218.068 | AV13: 406.693 | AW13: 1304.636 | AX13: 1490.297 | AY13: 2272.651 | AZ13: 1376.203 | BA13: 2176.015 | BB13: 1297.875 | BC13: 1957.97 | BD13: 2516.118 | BE13: 2763.825 | BF13: 2200.696 | BG13: 1265.357 | BH13: 1631.567 | BI13: 1522.824 | BJ13: 829.918 | BK13: =+'[2]8.25'!F13 -> 1818.559 | BL13: 813.3 | BM13: 1062.662 | BN13: 1284.348 | BO13: 1351.787 | BP13: 2109.274 | BQ13: 1394.903 | BR13: 1528.139 | BS13: 1685.096 | BT13: =+'5.26'!F13 -> 1032.408 | BV13: K3 | BW13: 1032.408 | BX13: 91.3 | BY13: =BX13/BW13 -> 0.08843403 | BZ13: =BX13/$BW$14 -> 0.0069592287
D14: TỔNG SL THƯC TẾ | E14: Tấn | F14: =+SUM(L14:S14) -> 66061.704 | G14: =+SUM(T14:AE14) -> 118965.14 | H14: =+SUM(AF14:AQ14) -> 123844.26 | I14: =+SUM(AR14:BC14) -> 120737.96 | J14: =+SUM(BD14:BO14) -> 148037.46 | K14: =+SUM(BP14:BU14) -> 64656.522 | L14: =+SUM(L11:L13) -> 2660.578 | M14: =+SUM(M11:M13) -> 6824.292 | N14: =+SUM(N11:N13) -> 7789.554 | O14: =+SUM(O11:O13) -> 9343.927 | P14: =+SUM(P11:P13) -> 9680.571 | Q14: =+SUM(Q11:Q13) -> 9683.983 | R14: =+SUM(R11:R13) -> 10314.424 | S14: =+SUM(S11:S13) -> 9764.375 | ... AG14: =+SUM(AG11:AG13) -> 9886.186 | AH14: 11142.714 | AI14: =+SUM(AI11:AI13) -> 8850.64 | AJ14: =+SUM(AJ11:AJ13) -> 11034.787 | AK14: =+SUM(AK11:AK13) -> 10585.406 | AL14: =+SUM(AL11:AL13) -> 9944.493 | AM14: 11316.79 | AN14: =+SUM(AN11:AN13) -> 10348.371 | AO14: =+SUM(AO11:AO13) -> 9548.02 | AP14: =+SUM(AP11:AP13) -> 11193.52 | AQ14: 11664.624 | AR14: 10949.658 | AS14: 10405.478 | AT14: 12015.436 | AU14: 8044.386 | AV14: 8745.759 | AW14: 9892.572 | AX14: 9639.878 | AY14: 9448.756 | AZ14: 10820.797 | BA14: 11266.508 | BB14: 8832.348 | BC14: 10676.382 | BD14: =SUM(BD11:BD13) -> 12622.077 | BE14: =SUM(BE11:BE13) -> 10974.284 | BF14: =SUM(BF11:BF13) -> 11173.264 | BG14: =SUM(BG11:BG13) -> 10772.566 | BH14: =SUM(BH11:BH13) -> 11716.072 | BI14: =SUM(BI11:BI13) -> 12276.994 | BJ14: =SUM(BJ11:BJ13) -> 13550.04 | BK14: =SUM(BK11:BK13) -> 13002.075 | ... BN14: =SUM(BN11:BN13) -> 12032.849 | BO14: 14055.761 | BP14: 13123.199 | BQ14: 12077.359 | BR14: 13311.084 | BS14: 13025.61 | BT14: =SUM(BT11:BT13) -> 13119.27 | BV14: Tổng | BW14: =SUM(BW11:BW13) -> 13119.27 | BX14: =SUM(BX11:BX13) -> 272.575 | BZ14: =SUM(BZ11:BZ13) -> 0.02077669
B15: Chênh lệch | C15: +, - | D15: GIẤY SÓNG | E15: Tấn | F15: =+F11-F7 -> -5888.6884 | G15: =+G11-G7 -> -1568.9088 | H15: =+H11-H7 -> -1259.3739 | I15: =+SUM(AR15:BC15) -> -696.44584 | J15: =+SUM(BD15:BT15) -> -1935.8362 | K15: =+SUM(BP15:BU15) -> -349.666 | L15: =+L11-L7 -> -2736.7491 | M15: =+M11-M7 -> 48.619979 | N15: =+N11-N7 -> -968.92472 | O15: =+O11-O7 -> -666.16263 | P15: =+P11-P7 -> -564.55799 | Q15: =+Q11-Q7 -> -589.03956 | R15: =+R11-R7 -> -192.1011 | S15: =+S11-S7 -> -219.7733 | ... AI15: =+AI11-AI7 -> -177.06114 | AJ15: -52.345704 | AK15: -30.253498 | AL15: -134.56579 | AM15: -125.41718 | AN15: -399.34294 | AO15: -242.40199 | AP15: -22.574709 | AQ15: =+AQ11-AQ7 -> -56.549037 | AR15: -190.34569 | AS15: -35.785942 | AT15: -23.60816 | AU15: -212.95881 | AV15: -26.431642 | AW15: -83.983148 | AX15: -23.348218 | AY15: -5.015 | AZ15: -41.252614 | BA15: -99.504245 | BB15: -145.93072 | BC15: 191.71834 | BD15: -62.145 | BE15: -186.85123 | BF15: -143.829 | BG15: -424.527 | BH15: -216.553 | BI15: 26.528 | BJ15: 2.195 | BK15: -63.955 | BL15: -17.097 | BM15: 1.241 | BN15: -392.157 | BO15: -109.02 | BP15: -210.498 | BQ15: -37.859 | BR15: -37.371 | BS15: 34.56 | BT15: =+'5.26'!F15 -> -98.498
D16: GIẤY MẶT | E16: Tấn | F16: =+F12-F8 -> -3229.2291 | G16: =+G12-G8 -> -1605.5993 | H16: =+H12-H8 -> -1803.0807 | I16: =+SUM(AR16:BC16) -> -4805.4922 | J16: =+SUM(BD16:BT16) -> -11311.053 | K16: =+SUM(BP16:BU16) -> -3086.632 | L16: =+L12-L8 -> 0 | M16: =+M12-M8 -> -358.99643 | N16: =+N12-N8 -> -51.062182 | O16: =+O12-O8 -> -372.66444 | P16: =+P12-P8 -> -160.88903 | Q16: =+Q12-Q8 -> -1224.1184 | R16: =+R12-R8 -> -481.90294 | S16: =+S12-S8 -> -579.59574 | ... AI16: =+AI12-AI8 -> -314.17642 | AJ16: -264.71939 | AK16: -106.10692 | AL16: -581.08038 | AM16: -125.46417 | AN16: -411.01539 | AO16: -374.87601 | AP16: -82.478116 | AQ16: =+AQ12-AQ8 -> -43.736455 | AR16: -280.8186 | AS16: -233.34695 | AT16: -399.24024 | AU16: -352.30756 | AV16: -152.88024 | AW16: -402.03837 | AX16: -720.14978 | AY16: -142.46465 | AZ16: 47.092908 | BA16: -322.88881 | BB16: -612.64188 | BC16: -1233.808 | BD16: -381.896 | BE16: -1012.1373 | BF16: -1333.603 | BG16: -818.264 | BH16: -303.942 | BI16: -677.358 | BJ16: -472.073 | BK16: -1008.171 | BL16: -1135.05 | BM16: -567.579 | BN16: -634.342 | BO16: 119.994 | BP16: -788.577 | BQ16: -389.685 | BR16: -634.684 | BS16: -584.046 | BT16: =+'5.26'!F16 -> -689.64
D17: GIẤY KRAFTLINE | E17: Tấn | F17: =+F13-F9 -> 0 | G17: =+G13-G9 -> -42.500759 | H17: =+H13-H9 -> -122.71847 | I17: =+SUM(AR17:BC17) -> -1071.0229 | J17: =+SUM(BD17:BT17) -> -1805.842 | K17: =+SUM(BP17:BU17) -> -242.18 | L17: =+L13-L9 -> 0 | M17: =+M13-M9 -> 0 | N17: =+N13-N9 -> 0 | O17: =+O13-O9 -> 0 | P17: =+P13-P9 -> 0 | Q17: =+Q13-Q9 -> 0 | R17: =+R13-R9 -> 0 | S17: =+S13-S9 -> 0 | ... AI17: =+AI13-AI9 -> 13.736342 | AJ17: 6.0403409 | AK17: -18.296068 | AL17: -8.0740535 | AM17: -50.37587 | AN17: -16.379553 | AO17: 7.1744438 | AP17: -13.108632 | AQ17: =+AQ13-AQ9 -> -5.1504292 | AR17: -38.303464 | AS17: 5.8875638 | AT17: -2.2830155 | AU17: -44.233948 | AV17: -4.0202979 | AW17: -137.21463 | AX17: -232.62397 | AY17: -85.349 | AZ17: -262.92972 | BA17: -118.08843 | BB17: -110.33563 | BC17: -41.528368 | BD17: -123.882 | BE17: -271.175 | BF17: -245.304 | BG17: -174.643 | BH17: -248.433 | BI17: 47.824 | BJ17: 19.918 | BK17: -127.064 | BL17: -221.7 | BM17: 126.662 | BN17: -190.652 | BO17: -155.213 | BP17: -77.726 | BQ17: -50.097 | BR17: -16.861 | BS17: -4.904 | BT17: =+'5.26'!F17 -> -92.592
D18: TỔNG CHÊNH | E18: Tấn | F18: =+SUM(F15:F17) -> -9117.9176 | G18: =+SUM(G15:G17) -> -3217.0089 | H18: =+SUM(H15:H17) -> -3185.1731 | I18: =+SUM(AR18:BC18) -> -6572.9609 | J18: =+SUM(BD18:BT18) -> -15052.732 | K18: =+SUM(BP18:BU18) -> -3678.478 | L18: =+SUM(L15:L17) -> -2736.7491 | M18: =+SUM(M15:M17) -> -310.37645 | N18: =+SUM(N15:N17) -> -1019.9869 | O18: =+SUM(O15:O17) -> -1038.8271 | P18: =+SUM(P15:P17) -> -725.44703 | Q18: =+SUM(Q15:Q17) -> -1813.1579 | R18: =+SUM(R15:R17) -> -674.00404 | S18: =+SUM(S15:S17) -> -799.36904 | ... AI18: =+SUM(AI15:AI17) -> -477.50122 | AJ18: -311.02476 | AK18: -154.65648 | AL18: -723.72022 | AM18: -301.25722 | AN18: -826.73789 | AO18: -610.10355 | AP18: -118.16146 | AQ18: =+SUM(AQ15:AQ17) -> -105.43592 | AR18: -509.46775 | AS18: -263.24533 | AT18: -425.13142 | AU18: -609.50032 | AV18: -183.33218 | AW18: -623.23614 | AX18: -976.12197 | AY18: -232.82865 | AZ18: -257.08943 | BA18: -540.48148 | BB18: -868.90823 | BC18: -1083.618 | BD18: -567.923 | BE18: -1470.1635 | BF18: -1722.736 | BG18: -1417.434 | BH18: -768.928 | BI18: -603.006 | BJ18: -449.96 | BK18: -1199.19 | BL18: -1373.847 | BM18: -439.676 | BN18: -1217.151 | BO18: -144.239 | BP18: -1076.801 | BQ18: -477.641 | BR18: -688.916 | BS18: -554.39 | BT18: =+'5.26'!F18 -> -880.73
B19: Các hang mục liên quan đến | C19: Dừng bất thường | D19: Dừng bất thường đứt giấy | E19: Lần | F19: =+SUM(L19:S19) -> 552 | G19: =+SUM(T19:AE19) -> 498 | H19: =+SUM(AF19:AQ19) -> 404 | I19: =+SUM(AR19:BC19) -> 427 | J19: =+SUM(BD19:BT19) -> 507 | K19: =+SUM(BP19:BU19) -> 137 | L19: 3 | M19: 90 | N19: 79 | O19: 80 | P19: 72 | Q19: 96 | R19: 68 | S19: 64 | T19: 63 | U19: 56 | V19: 58 | W19: 74 | X19: 51 | Y19: 44 | Z19: 34 | AA19: 41 | AB19: 11 | AC19: 21 | AD19: 20 | AE19: 25 | AF19: 32 | AG19: 8 | AH19: 13 | AI19: 4 | AJ19: 31 | AK19: 37 | AL19: 33 | AM19: 64 | AN19: 61 | AO19: 53 | AP19: 37 | AQ19: 31 | AR19: 49 | AS19: 49 | AT19: 62 | AU19: 30 | AV19: 26 | AW19: 23 | AX19: 24 | AY19: 22 | AZ19: 15 | BA19: 49 | BB19: 29 | BC19: 49 | BD19: 9 | BE19: 42 | BF19: 42 | BG19: 53 | BH19: 36 | BI19: 25 | BJ19: 35 | BK19: 25 | BL19: 17 | BM19: 37 | BN19: 20 | BO19: 29 | BP19: 51 | BQ19: 20 | BR19: 10 | BS19: 15 | BT19: =+'5.26'!F19 -> 41
E20: Tấn tp | F20: =+SUM(L20:S20) -> 3002.8758 | G20: =+SUM(T20:AE20) -> 1827.6667 | H20: =+SUM(AF20:AQ20) -> 1305 | I20: =+SUM(AR20:BC20) -> 1901 | J20: =+SUM(BD20:BT20) -> 2477 | K20: =+SUM(BP20:BU20) -> 635 | L20: 79 | M20: 51 | N20: 278 | O20: 666 | P20: 333 | Q20: 836 | R20: 331.7 | S20: 428.17577 | T20: 298 | U20: 130 | V20: 113 | W20: 194.66667 | X20: 244 | Y20: 101 | Z20: 134 | AA20: 248 | AB20: 39 | AC20: 95 | AD20: 71 | AE20: 160 | AF20: 82 | AG20: 54 | AH20: 46 | AI20: 15 | AJ20: 130 | AK20: 111 | AL20: 97 | AM20: 190 | AN20: 186 | AO20: 204 | AP20: 138 | AQ20: 52 | AR20: 254 | AS20: 245 | AT20: 288 | AU20: 142 | AV20: 97 | AW20: 67 | AX20: 104 | AY20: 124 | AZ20: 44 | BA20: 245 | BB20: 105 | BC20: 186 | BD20: 40 | BE20: 224 | BF20: 223 | BG20: 216 | BH20: 153 | BI20: 66 | BJ20: 164 | BK20: 129 | BL20: 79 | BM20: 248 | BN20: 89 | BO20: 211 | BP20: 271 | BQ20: 67 | BR20: 54 | BS20: 53 | BT20: =+'5.26'!F20 -> 190
D21: Dừng bất thường khác | E21: Lần | F21: =+SUM(L21:S21) -> 119 | G21: =+SUM(T21:AE21) -> 55 | H21: =+SUM(AF21:AQ21) -> 104 | I21: =+SUM(AR21:BC21) -> 115 | J21: =+SUM(BD21:BT21) -> 199 | K21: =+SUM(BP21:BU21) -> 49 | L21: 11 | M21: 9 | N21: 9 | O21: 12 | P21: 49 | Q21: 12 | R21: 9 | S21: 8 | T21: 3 | U21: 4 | V21: 2 | W21: 4 | X21: 5 | Y21: 2 | Z21: 6 | AA21: 4 | AB21: 6 | AC21: 8 | AD21: 8 | AE21: 3 | AF21: 2 | AG21: 3 | AH21: 6 | AI21: 1 | AJ21: 20 | AK21: 9 | AL21: 13 | AM21: 9 | AN21: 11 | AO21: 18 | AP21: 5 | AQ21: 7 | AR21: 6 | AS21: 3 | AT21: 6 | AU21: 18 | AV21: 5 | AW21: 16 | AX21: 16 | AY21: 8 | AZ21: 5 | BA21: 11 | BB21: 15 | BC21: 6 | BD21: 12 | BE21: 19 | BF21: 23 | BG21: 20 | BH21: 13 | BI21: 9 | BJ21: 15 | BK21: 4 | BL21: 13 | BM21: 7 | BN21: 8 | BO21: 7 | BP21: 16 | BQ21: 3 | BR21: 10 | BS21: 10 | BT21: =+'5.26'!F21 -> 10
E22: Tấn tp | F22: =+SUM(L22:S22) -> 4027.6 | G22: =+SUM(T22:AE22) -> 1940 | H22: =+SUM(AF22:AQ22) -> 2718 | I22: =+SUM(AR22:BC22) -> 4169 | J22: =+SUM(BD22:BT22) -> 9105 | K22: =+SUM(BP22:BU22) -> 1826 | L22: 424 | M22: 734 | N22: 553 | O22: 514 | P22: 425 | Q22: 595 | R22: 327 | S22: 455.6 | T22: 153 | U22: 145 | V22: 181 | W22: 121 | X22: 127 | Y22: 24 | Z22: 154 | AA22: 51 | AB22: 226 | AC22: 223 | AD22: 471 | AE22: 64 | AF22: 37 | AG22: 69 | AH22: 33 | AI22: 15 | AJ22: 272 | AK22: 122 | AL22: 701 | AM22: 144 | AN22: 571 | AO22: 476 | AP22: 97 | AQ22: 181 | AR22: 175 | AS22: 34 | AT22: 235 | AU22: 497 | AV22: 95 | AW22: 664 | AX22: 823 | AY22: 182 | AZ22: 295 | BA22: 263 | BB22: 487 | BC22: 419 | BD22: 424 | BE22: 606 | BF22: 906 | BG22: 456 | BH22: 434 | BI22: 952 | BJ22: 871 | BK22: 192 | BL22: 987 | BM22: 217 | BN22: 763 | BO22: 471 | BP22: 478 | BQ22: 65 | BR22: 677 | BS22: 283 | BT22: =+'5.26'!F22 -> 323
C23: Dừng kế hoạch | D23: Dừng kế hoạch NHƯNG LÀ KH PHÁT SINH | E23: Lần | F23: =+SUM(L23:S23) -> 5 | G23: =+SUM(T23:AE23) -> 1 | H23: =+SUM(AF23:AQ23) -> 2 | I23: =+SUM(AR23:BC23) -> 0 | J23: =+SUM(BD23:BT23) -> 6 | K23: =+SUM(BP23:BU23) -> 3 | L23: 0 | M23: 0 | N23: 1 | O23: 0 | P23: 2 | Q23: 0 | R23: 1 | S23: 1 | T23: 0 | U23: 0 | V23: 0 | W23: 1 | X23: 0 | Y23: 0 | Z23: 0 | AA23: 0 | AB23: 0 | AC23: 0 | AD23: 0 | AE23: 0 | AF23: 0 | AG23: 0 | AH23: 1 | AI23: 0 | AJ23: 1 | AK23: 0 | AL23: 0 | AM23: 0 | AN23: 0 | AO23: 0 | AP23: 0 | AQ23: 0 | AR23: 0 | AS23: 0 | AT23: 0 | AU23: 0 | AV23: 0 | AW23: 0 | AX23: 0 | AY23: 0 | AZ23: 0 | BA23: 0 | BB23: 0 | BC23: 0 | BD23: 0 | BE23: 0 | BF23: 1 | BG23: 1 | BH23: 0 | BI23: 0 | BJ23: 0 | BK23: 0 | BL23: 0 | BM23: 0 | BN23: 0 | BO23: 1 | BP23: 0 | BQ23: 0 | BR23: 1 | BS23: 0 | BT23: =+'5.26'!F23 -> 2
E24: Tấn tp | F24: =+SUM(L24:S24) -> 343.9 | G24: =+SUM(T24:AE24) -> 75 | H24: =+SUM(AF24:AQ24) -> 30 | I24: =+SUM(AR24:BC24) -> 0 | J24: =+SUM(BD24:BT24) -> 451 | K24: =+SUM(BP24:BU24) -> 120 | L24: 0 | M24: 0 | N24: 260 | O24: 0 | P24: 30 | Q24: 0 | R24: 17.9 | S24: 36 | T24: 0 | U24: 0 | V24: 0 | W24: 70 | X24: 0 | Y24: 0 | Z24: 5 | AA24: 0 | AB24: 0 | AC24: 0 | AD24: 0 | AE24: 0 | AF24: 0 | AG24: 0 | AH24: 10 | AI24: 0 | AJ24: 20 | AK24: 0 | AL24: 0 | AM24: 0 | AN24: 0 | AO24: 0 | AP24: 0 | AQ24: 0 | AR24: 0 | AS24: 0 | AT24: 0 | AU24: 0 | AV24: 0 | AW24: 0 | AX24: 0 | AY24: 0 | AZ24: 0 | BA24: 0 | BB24: 0 | BC24: 0 | BD24: 0 | BE24: 0 | BF24: 60 | BG24: 240 | BH24: 0 | BI24: 0 | BJ24: 0 | BK24: 0 | BL24: 0 | BM24: 0 | BN24: 0 | BO24: 31 | BP24: 0 | BQ24: 0 | BR24: 20 | BS24: 0 | BT24: =+'5.26'!F24 -> 100
C25: Khác | D25: Giảm tốc độ so với kế hoạch | E25: Lần | F25: =+SUM(L25:S25) -> 8 | G25: =+SUM(T25:AE25) -> 78 | H25: =+SUM(AF25:AQ25) -> 22 | I25: =+SUM(AR25:BC25) -> 21 | J25: =+SUM(BD25:BT25) -> 206 | K25: =+SUM(BP25:BU25) -> 77 | L25: 0 | M25: 0 | N25: 1 | O25: 0 | P25: 0 | Q25: 0 | R25: 2 | S25: 5 | T25: 4 | U25: 4 | V25: 4 | W25: 2 | X25: 0 | Y25: 0 | Z25: 47 | AA25: 0 | AB25: 2 | AC25: 0 | AD25: 6 | AE25: 9 | AF25: 3 | AG25: 3 | AH25: 0 | AI25: 0 | AJ25: 2 | AK25: 3 | AL25: 1 | AM25: 7 | AN25: 3 | AO25: 0 | AP25: 0 | AQ25: 0 | AR25: 0 | AS25: 0 | AT25: 0 | AU25: 0 | AV25: 0 | AW25: 0 | AX25: 0 | AY25: 0 | AZ25: 0 | BA25: 0 | BB25: 10 | BC25: 11 | BD25: 9 | BE25: 15 | BF25: 18 | BG25: 23 | BH25: 15 | BI25: 3 | BJ25: 2 | BK25: 2 | BL25: 12 | BM25: 9 | BN25: 14 | BO25: 7 | BP25: 12 | BQ25: 19 | BR25: 13 | BS25: 18 | BT25: =+'5.26'!F25 -> 15
E26: Tấn tp | F26: =+SUM(L26:S26) -> 162.73333 | G26: =+SUM(T26:AE26) -> 565 | H26: =+SUM(AF26:AQ26) -> 197 | I26: =+SUM(AR26:BC26) -> 555 | J26: =+SUM(BD26:BT26) -> 4705 | K26: =+SUM(BP26:BU26) -> 1480 | L26: 0 | M26: 0 | N26: 10 | O26: 0 | P26: 0 | Q26: 0 | R26: 36.8 | S26: 115.93333 | T26: 79 | U26: 43 | V26: 42 | W26: 60 | X26: 2 | Y26: 0 | Z26: 33 | AA26: 0 | AB26: 11 | AC26: 0 | AD26: 101 | AE26: 194 | AF26: 50 | AG26: 25 | AH26: 0 | AI26: 0 | AJ26: 19 | AK26: 23 | AL26: 4 | AM26: 44 | AN26: 32 | AO26: 0 | AP26: 0 | AQ26: 0 | AR26: 0 | AS26: 0 | AT26: 0 | AU26: 0 | AV26: 0 | AW26: 0 | AX26: 0 | AY26: 0 | AZ26: 0 | BA26: 0 | BB26: 290 | BC26: 265 | BD26: 226 | BE26: 575 | BF26: 533 | BG26: 506 | BH26: 434 | BI26: 46 | BJ26: 35 | BK26: 75 | BL26: 230 | BM26: 151 | BN26: 325 | BO26: 89 | BP26: 315 | BQ26: 437 | BR26: 259 | BS26: 212 | BT26: =+'5.26'!F26 -> 257
C27: Sự cố chất lượng | D27: Hủy hàng do lỗi chất lượng | E27: Lần | F27: =+SUM(L27:S27) -> 0 | G27: =+SUM(T27:AE27) -> 21 | H27: =+SUM(AF27:AQ27) -> 1 | I27: =+SUM(AR27:BC27) -> 0 | J27: =+SUM(BD27:BT27) -> 4 | K27: =+SUM(BP27:BU27) -> 0 | L27: 0 | M27: 0 | N27: 0 | O27: 0 | P27: 0 | Q27: 0 | R27: 0 | S27: 0 | T27: 0 | U27: 0 | V27: 0 | W27: 0 | X27: 17 | Y27: 0 | Z27: 1 | AA27: 0 | AB27: 1 | AC27: 0 | AD27: 2 | AE27: 0 | AF27: 0 | AG27: 0 | AH27: 0 | AI27: 0 | AJ27: 0 | AK27: 0 | AL27: 0 | AM27: 1 | AN27: 0 | AO27: 0 | AP27: 0 | AQ27: 0 | AR27: 0 | AS27: 0 | AT27: 0 | AU27: 0 | AV27: 0 | AW27: 0 | AX27: 0 | AY27: 0 | AZ27: 0 | BA27: 0 | BB27: 0 | BC27: 0 | BD27: 0 | BE27: 3 | BF27: 1 | BG27: 0 | BH27: 0 | BI27: 0 | BJ27: 0 | BK27: 0 | BL27: 0 | BM27: 0 | BN27: 0 | BO27: 0 | BP27: 0 | BQ27: 0 | BR27: 0 | BS27: 0 | BT27: =+'5.26'!F27 -> 0
E28: Tấn tp | F28: =+SUM(L28:S28) -> 0 | G28: =+SUM(T28:AE28) -> 24 | H28: =+SUM(AF28:AQ28) -> 8 | I28: =+SUM(AR28:BC28) -> 0 | J28: =+SUM(BD28:BT28) -> 86 | K28: =+SUM(BP28:BU28) -> 0 | L28: 0 | M28: 0 | N28: 0 | O28: 0 | P28: 0 | Q28: 0 | R28: 0 | S28: 0 | T28: 0 | U28: 0 | V28: 0 | W28: 0 | X28: 0 | Y28: 0 | Z28: 8 | AA28: 0 | AB28: 8 | AC28: 0 | AD28: 8 | AE28: 0 | AF28: 0 | AG28: 0 | AH28: 0 | AI28: 0 | AJ28: 0 | AK28: 0 | AL28: 0 | AM28: 8 | AN28: 0 | AO28: 0 | AP28: 0 | AQ28: 0 | AR28: 0 | AS28: 0 | AT28: 0 | AU28: 0 | AV28: 0 | AW28: 0 | AX28: 0 | AY28: 0 | AZ28: 0 | BA28: 0 | BB28: 0 | BC28: 0 | BD28: 0 | BE28: 66 | BF28: 20 | BG28: 0 | BH28: 0 | BI28: 0 | BJ28: 0 | BK28: 0 | BL28: 0 | BM28: 0 | BN28: 0 | BO28: 0 | BP28: 0 | BQ28: 0 | BR28: 0 | BS28: 0 | BT28: =+'5.26'!F28 -> 0
C29: TỔNG ẢNH HƯỞNG | E29: Lần | F29: =+SUM(L29:S29) -> 684 | G29: =+SUM(T29:AE29) -> 653 | H29: =+SUM(AF29:AQ29) -> 533 | I29: =+SUM(AR29:BC29) -> 563 | J29: =+SUM(BD29:BT29) -> 1019 | K29: =+SUM(BP29:BU29) -> 266 | L29: =+L19+L21+L23+L25+L27 -> 14 | M29: =+M19+M21+M23+M25+M27 -> 99 | N29: =+N19+N21+N23+N25+N27 -> 90 | O29: =+O19+O21+O23+O25+O27 -> 92 | P29: =+P19+P21+P23+P25+P27 -> 123 | Q29: =+Q19+Q21+Q23+Q25+Q27 -> 108 | R29: =+R19+R21+R23+R25+R27 -> 80 | S29: =+S19+S21+S23+S25+S27 -> 78 | ... AE29: =+AE19+AE21+AE23+AE25+AE27 -> 37 | AF29: 37 | AG29: 14 | AH29: 20 | AI29: 5 | AJ29: 54 | AK29: 49 | AL29: 47 | AM29: 81 | AN29: 75 | AO29: 71 | AP29: 42 | AQ29: 38 | AR29: 55 | AS29: 52 | AT29: 68 | AU29: 48 | AV29: 31 | AW29: 39 | AX29: 40 | AY29: 30 | AZ29: 20 | BA29: 60 | BB29: 54 | BC29: 66 | BD29: 32 | BE29: 104 | BF29: 133 | BG29: 119 | BH29: 64 | BI29: 37 | BJ29: 52 | BK29: 31 | BL29: 42 | BM29: 53 | BN29: 42 | BO29: 44 | BP29: 79 | BQ29: 42 | BR29: 34 | BS29: 43 | BT29: =+'5.26'!F29 -> 68
E30: Tấn tp | F30: =+SUM(L30:S30) -> 7537.1091 | G30: =+SUM(T30:AE30) -> 4431.6667 | H30: =+SUM(AF30:AQ30) -> 4258 | I30: =+SUM(AR30:BC30) -> 6561 | J30: =+SUM(BD30:BT30) -> 16821 | K30: =+SUM(BP30:BU30) -> 4061 | L30: =+L20+L22+L24+L26+L28 -> 503 | M30: =+M20+M22+M24+M26+M28 -> 785 | N30: =+N20+N22+N24+N26+N28 -> 1101 | O30: =+O20+O22+O24+O26+O28 -> 1180 | P30: =+P20+P22+P24+P26+P28 -> 788 | Q30: =+Q20+Q22+Q24+Q26+Q28 -> 1431 | R30: =+R20+R22+R24+R26+R28 -> 713.4 | S30: =+S20+S22+S24+S26+S28 -> 1035.7091 | ... AE30: =+AE20+AE22+AE24+AE26+AE28 -> 418 | AF30: 169 | AG30: 148 | AH30: 89 | AI30: 30 | AJ30: 441 | AK30: 256 | AL30: 802 | AM30: 386 | AN30: 789 | AO30: 680 | AP30: 235 | AQ30: 233 | AR30: 429 | AS30: 260 | AT30: 503 | AU30: 641 | AV30: 184 | AW30: 725 | AX30: 923 | AY30: 306 | AZ30: 339 | BA30: 499 | BB30: 882 | BC30: 870 | BD30: 690 | BE30: 1471 | BF30: 1739 | BG30: 1418 | BH30: 1021 | BI30: 1064 | BJ30: 1070 | BK30: 396 | BL30: 1296 | BM30: 616 | BN30: 1177 | BO30: 802 | BP30: 1064 | BQ30: 569 | BR30: 1010 | BS30: 548 | BT30: =+'5.26'!F30 -> 870
B31: Tỷ lệ đạt | E31: % | F31: =F14/F10 -> 0.87871823 | G31: =G14/G10 -> 0.97367038 | H31: =H14/H10 -> 0.97492571 | I31: =I14/I10 -> 0.9483708 | J31: =J14/J10 -> 0.92871681 | K31: =K14/K10 -> 0.94616993 | L31: =L14/L10 -> 0.49294363 | M31: =M14/M10 -> 0.95649742 | ... BN31: =BN14/BN10 -> 0.90813955 | BO31: 0.98984232 | BP31: 0.92416894 | BQ31: 0.96195611 | BR31: 0.95079171 | BS31: 0.95917599 | BT31: =BT14/BT10 -> 0.93709071

Sheet BIỂU ĐỒ
Q1: CÔNG TY TNHH MIZA NGHI SƠN | AB1: THEO DÕI THỰC TẾ SẢN LƯỢNG HÀNG NGÀY DÂY CHUYỀN PM3
Q2: LINE | S2: PM3
BU3: u
K4: ` | Q4: Các điểm lưu ý : Các hạng mục Tổng hợp (II) ( III) và ( IV ) sẽ thực hiện tổng hợp / đánh giá kết thúc mỗi THÁNG hoặc TUẦN
B6: II.TỔNG HƠP YẾU TỐ ẢNH HƯỞNG ĐẾN TỶ LỆ ĐẠT KẾ HOẠCH | Q6: I.TÌNH HÌNH THỰC TẾ SẢN LƯỢNG& TỶ LỆ ĐẠT KẾ HOẠCH THÁNG/ NĂM | AO6: II .TÌNH HÌNH THỰC TẾ SẢN LƯỢNG HÀNG NGÀY
B7: 1. THEO CÁC HANG MỤC VỚI SỐ LẦN PHÁT SINH | V7: 2021 | W7: 2022 | X7: 2023 | Y7: 2024 | Z7: 2025 | AA7: 2026 | AB7: 2026
AB8: Tháng 1 | AC8: Tháng 2 | AD8: Tháng 3 | AE8: Tháng 4 | AF8: Tháng 5 | AG8: Tháng 6 | AH8: Tháng 7 | AI8: Tháng 8 | AJ8: Tháng 9 | AK8: Tháng 10 | AL8: Tháng 11 | AM8: Tháng 12 | AO8: 1 | AP8: 2 | AQ8: 3 | AR8: 4 | AS8: 5 | AT8: 6 | AU8: 7 | AV8: 8 | AW8: 9 | AX8: 10 | AY8: 11 | AZ8: 12 | BA8: 13 | BB8: 14 | BC8: 15 | BD8: 16 | BE8: 17 | BF8: 18 | BG8: 19 | BH8: 20 | BI8: 21 | BJ8: 22 | BK8: 23 | BL8: 24 | BM8: 25 | BN8: 26 | BO8: 27 | BP8: 28 | BQ8: 29 | BR8: 30 | BS8: 31
Q9: SẢN LƯỢNG , TỶ LỆ ĐẠT KẾ HOẠCH- THƯC TẾ | R9: ĐÁNH GIÁ SX GIẤY MẶT
S10: Tỷ lệ đạt THỰC TẾ - Kraftlinet | U10: % | W10: 0.96921824 | X10: 0.98295916 | Y10: 0.94599571 | Z10: 0.93245153 | AA10: =IF(SUM(AB10:AM10)=0,0,AVERAGE(AB10:AM10)) -> #DIV/0! | AB10: =IF(AB$35=0,"-",IF(AB35=0,"-",AB35/AB$31)) -> 0.96445999 | AC10: =IF(AC$35=0,"-",IF(AC35=0,"-",AC35/AC$31)) -> 0.9653308 | AD10: =IF(AD$35=0,"-",IF(AD35=0,"-",AD35/AD$31)) -> 0.98908673 | AE10: =IF(AE$35=0,"-",IF(AE35=0,"-",AE35/AE$31)) -> 0.99709822 | AF10: =IF(AF$35=0,"-",IF(AF35=0,"-",AF35/AF$31)) -> 0.917696 | AG10: =IF(AG$35=0,"-",IF(AG35=0,"-",AG35/AG$31)) -> #DIV/0! | AH10: =IF(AH$35=0,"-",IF(AH35=0,"-",AH35/AH$31)) -> #DIV/0! | AI10: =IF(AI$35=0,"-",IF(AI35=0,"-",AI35/AI$31)) -> - | ... AM10: =IF(AM$35=0,"-",IF(AM35=0,"-",AM35/AM$31)) -> - | AO10: =IF(AO$35=0,"-",IF(AO35=0,"-",AO35/AO$31)) -> - | AP10: =IF(AP$35=0,"-",IF(AP35=0,"-",AP35/AP$31)) -> - | AQ10: =IF(AQ$35=0,"-",IF(AQ35=0,"-",AQ35/AQ$31)) -> - | AR10: =IF(AR$35=0,"-",IF(AR35=0,"-",AR35/AR$31)) -> - | AS10: =IF(AS$35=0,"-",IF(AS35=0,"-",AS35/AS$31)) -> - | AT10: =IF(AT$35=0,"-",IF(AT35=0,"-",AT35/AT$31)) -> - | AU10: =IF(AU$35=0,"-",IF(AU35=0,"-",AU35/AU$31)) -> - | AV10: =IF(AV$35=0,"-",IF(AV35=0,"-",AV35/AV$31)) -> - | ... BS10: =IF(BS$35=0,"-",IF(BS35=0,"-",BS35/BS$31)) -> 0.857348
S11: Tỷ lệ đạt THỰC TẾ -GIẤY MẶT | U11: % | V11: 0.88382384 | W11: 0.98037338 | X11: 0.97833539 | Y11: 0.94952738 | Z11: 0.93021104 | AA11: =IF(SUM(AB11:AM11)=0,0,AVERAGE(AB11:AM11)) -> #DIV/0! | AB11: =IF(AB$34=0,"-",IF(AB34=0,"-",AB34/AB$30)) -> 0.92698361 | AC11: =IF(AC$34=0,"-",IF(AC34=0,"-",AC34/AC$30)) -> 0.96234928 | AD11: =IF(AD$34=0,"-",IF(AD34=0,"-",AD34/AD$30)) -> 0.94568387 | AE11: =IF(AE$34=0,"-",IF(AE34=0,"-",AE34/AE$30)) -> 0.94313087 | AF11: =IF(AF$34=0,"-",IF(AF34=0,"-",AF34/AF$30)) -> 0.94172877 | AG11: =IF(AG$34=0,"-",IF(AG34=0,"-",AG34/AG$30)) -> #DIV/0! | AH11: =IF(AH$34=0,"-",IF(AH34=0,"-",AH34/AH$30)) -> #DIV/0! | AI11: =IF(AI$34=0,"-",IF(AI34=0,"-",AI34/AI$30)) -> - | ... AM11: =IF(AM$34=0,"-",IF(AM34=0,"-",AM34/AM$30)) -> - | AO11: =IF(AO$34=0,"-",IF(AO34=0,"-",AO34/AO$30)) -> 0.87175 | AP11: =IF(AP$34=0,"-",IF(AP34=0,"-",AP34/AP$30)) -> 0.95314571 | AQ11: =IF(AQ$34=0,"-",IF(AQ34=0,"-",AQ34/AQ$30)) -> 0.85085957 | AR11: =IF(AR$34=0,"-",IF(AR34=0,"-",AR34/AR$30)) -> 0.92270612 | AS11: =IF(AS$34=0,"-",IF(AS34=0,"-",AS34/AS$30)) -> 1.01505 | AT11: =IF(AT$34=0,"-",IF(AT34=0,"-",AT34/AT$30)) -> 0.99312885 | AU11: =IF(AU$34=0,"-",IF(AU34=0,"-",AU34/AU$30)) -> 1.0022551 | AV11: =IF(AV$34=0,"-",IF(AV34=0,"-",AV34/AV$30)) -> 0.96844 | ... BS11: =IF(BS$34=0,"-",IF(BS34=0,"-",BS34/BS$30)) -> -
S12: Đánh giá | U12: - | V12: =IF(V34=0," ",IF(V11>0.95,"O",IF(V11<0.85,"X","Δ"))) -> Δ | W12: =IF(W34=0," ",IF(W11>0.95,"O",IF(W11<0.85,"X","Δ"))) -> O | X12: =IF(X34=0," ",IF(X11>0.95,"O",IF(X11<0.85,"X","Δ"))) -> O | Y12: =IF(Y34=0," ",IF(Y11>0.95,"O",IF(Y11<0.85,"X","Δ"))) -> Δ | Z12: =IF(Z34=0," ",IF(Z11>0.95,"O",IF(Z11<0.85,"X","Δ"))) -> Δ | AA12: =IF(AA34=0," ",IF(AA11>0.95,"O",IF(AA11<0.85,"X","Δ"))) -> #DIV/0! | AB12: =IF(AB34=0," ",IF(AB11>0.95,"O",IF(AB11<0.9,"X","Δ"))) -> Δ | AC12: =IF(AC34=0," ",IF(AC11>0.95,"O",IF(AC11<0.9,"X","Δ"))) -> O | AD12: =IF(AD34=0," ",IF(AD11>0.95,"O",IF(AD11<0.9,"X","Δ"))) -> Δ | AE12: =IF(AE34=0," ",IF(AE11>0.95,"O",IF(AE11<0.9,"X","Δ"))) -> Δ | AF12: =IF(AF34=0," ",IF(AF11>0.95,"O",IF(AF11<0.9,"X","Δ"))) -> Δ | AG12: =IF(AG34=0," ",IF(AG11>0.95,"O",IF(AG11<0.9,"X","Δ"))) -> #DIV/0! | AH12: =IF(AH34=0," ",IF(AH11>0.95,"O",IF(AH11<0.9,"X","Δ"))) -> #DIV/0! | AI12: =IF(AI34=0," ",IF(AI11>0.95,"O",IF(AI11<0.9,"X","Δ"))) | ... AM12: =IF(AM34=0," ",IF(AM11>0.95,"O",IF(AM11<0.9,"X","Δ"))) | AO12: =IF(AO34=0," ",IF(AO11>0.949,"O",IF(AO11<0.9,"X","Δ"))) -> X | AP12: =IF(AP34=0," ",IF(AP11>0.949,"O",IF(AP11<0.9,"X","Δ"))) -> O | AQ12: =IF(AQ34=0," ",IF(AQ11>0.949,"O",IF(AQ11<0.9,"X","Δ"))) -> X | AR12: =IF(AR34=0," ",IF(AR11>0.949,"O",IF(AR11<0.9,"X","Δ"))) -> Δ | AS12: =IF(AS34=0," ",IF(AS11>0.949,"O",IF(AS11<0.9,"X","Δ"))) -> O | AT12: =IF(AT34=0," ",IF(AT11>0.949,"O",IF(AT11<0.9,"X","Δ"))) -> O | AU12: =IF(AU34=0," ",IF(AU11>0.949,"O",IF(AU11<0.9,"X","Δ"))) -> O | AV12: =IF(AV34=0," ",IF(AV11>0.949,"O",IF(AV11<0.9,"X","Δ"))) -> O | ... BS12: =IF(BS34=0," ",IF(BS11>0.949,"O",IF(BS11<0.9,"X","Δ")))
R13: ĐÁNH GIÁ SX TỔNG DÂY CHUYỀN
S14: Tỷ lệ đạt THƯC TẾ -TOTAL | U14: % | V14: 0.85864724 | W14: 0.97322848 | X14: 0.9724611 | Y14: =+Y36/Y32 -> 0.9483708 | Z14: =+Z36/Z32 -> 0.92871681 | AA14: =+AA36/AA32 -> 0.94616993 | AB14: =AB36/AB32 -> 0.92416894 | AC14: =AC36/AC32 -> 0.96195611 | AD14: =AD36/AD32 -> 0.95079171 | AE14: =AE36/AE32 -> 0.95917599 | AF14: =AF36/AF32 -> 0.93709071 | AG14: =AG36/AG32 -> #DIV/0! | AH14: =AH36/AH32 -> #DIV/0! | AI14: =AI36/AI32 -> #DIV/0! | ... AM14: =AM36/AM32 -> #DIV/0! | AO14: =IFERROR((AO36/AO32),0) -> 0.89225143 | AP14: =IFERROR((AP36/AP32),0) -> 0.96173571 | AQ14: =IFERROR((AQ36/AQ32),0) -> 0.852975 | AR14: =IFERROR((AR36/AR32),0) -> 0.92270612 | AS14: =IFERROR((AS36/AS32),0) -> 1.01505 | AT14: =IFERROR((AT36/AT32),0) -> 0.99312885 | AU14: =IFERROR((AU36/AU32),0) -> 1.0022551 | AV14: =IFERROR((AV36/AV32),0) -> 0.96844 | ... BS14: =IFERROR((BS36/BS32),0) -> 0.857348
S15: Đánh giá | U15: - | V15: =IF(V36=0,"",IF(V14>0.95,"O",IF(V14<0.85,"X","Δ"))) -> Δ | W15: =IF(W36=0,"",IF(W14>0.95,"O",IF(W14<0.85,"X","Δ"))) -> O | X15: =IF(X36=0,"",IF(X14>0.95,"O",IF(X14<0.85,"X","Δ"))) -> O | Y15: =IF(Y36=0,"",IF(Y14>0.95,"O",IF(Y14<0.85,"X","Δ"))) -> Δ | Z15: =IF(Z36=0,"",IF(Z14>0.95,"O",IF(Z14<0.85,"X","Δ"))) -> Δ | AA15: =IF(AA36=0,"",IF(AA14>0.95,"O",IF(AA14<0.9,"X","Δ"))) -> Δ | AB15: =IF(AB36=0,"",IF(AB14>0.95,"O",IF(AB14<0.9,"X","Δ"))) -> Δ | AC15: =IF(AC36=0,"",IF(AC14>0.95,"O",IF(AC14<0.9,"X","Δ"))) -> O | AD15: =IF(AD36=0,"",IF(AD14>0.95,"O",IF(AD14<0.9,"X","Δ"))) -> O | AE15: =IF(AE36=0,"",IF(AE14>0.95,"O",IF(AE14<0.9,"X","Δ"))) -> O | AF15: =IF(AF36=0,"",IF(AF14>0.95,"O",IF(AF14<0.9,"X","Δ"))) -> Δ | AG15: =IF(AG36=0,"",IF(AG14>0.95,"O",IF(AG14<0.9,"X","Δ"))) -> #DIV/0! | AH15: =IF(AH36=0,"",IF(AH14>0.95,"O",IF(AH14<0.9,"X","Δ"))) -> #DIV/0! | ... AM15: =IF(AM36=0,"",IF(AM14>0.95,"O",IF(AM14<0.9,"X","Δ"))) | AO15: =IF(AO36=0,"",IF(AO14>0.949,"O",IF(AO14<0.9,"X","Δ"))) -> X | AP15: =IF(AP36=0,"",IF(AP14>0.949,"O",IF(AP14<0.9,"X","Δ"))) -> O | AQ15: =IF(AQ36=0,"",IF(AQ14>0.949,"O",IF(AQ14<0.9,"X","Δ"))) -> X | AR15: =IF(AR36=0,"",IF(AR14>0.949,"O",IF(AR14<0.9,"X","Δ"))) -> Δ | AS15: =IF(AS36=0,"",IF(AS14>0.949,"O",IF(AS14<0.9,"X","Δ"))) -> O | AT15: =IF(AT36=0,"",IF(AT14>0.949,"O",IF(AT14<0.9,"X","Δ"))) -> O | AU15: =IF(AU36=0,"",IF(AU14>0.949,"O",IF(AU14<0.9,"X","Δ"))) -> O | AV15: =IF(AV36=0,"",IF(AV14>0.949,"O",IF(AV14<0.9,"X","Δ"))) -> O | ... BS15: =IF(BS36=0,"",IF(BS14>0.949,"O",IF(BS14<0.9,"X","Δ"))) -> X
R16: TỔNG-SẢN LƯỢNG LŨY KẾ
B17: 2.THEO CÁC HANG MỤC THEO SỐ TẤN THÀNH PHẨM | S17: KH | T17: SL Lũy kế Tổng -KH | U17: Tấn | V17: =V32 -> 75179.622 | W17: =W32 -> 122182.15 | X17: =X32 -> 127029.43 | Y17: =Y32 -> 127310.92 | Z17: =Z32 -> 159400 | AA17: =AA32 -> 68335 | AB17: =+AB32 -> 14200 | AC17: =+AC32 -> 12555 | AD17: =+AD32 -> 14000 | AE17: =+AE32 -> 13580 | AF17: =+AF32 -> 14000 | AG17: =+AG32 -> 0 | AH17: =+AH32 -> 0 | AI17: =+AI32 -> 0 | ... AM17: =+AM32 -> 0 | AO17: =+AN17+AO32 -> 350 | AP17: =+AO17+AP32 -> 770 | AQ17: =+AP17+AQ32 -> 1250 | AR17: =+AQ17+AR32 -> 1740 | AS17: =+AR17+AS32 -> 2240 | AT17: =+AS17+AT32 -> 2760 | AU17: =+AT17+AU32 -> 3250 | AV17: =+AU17+AV32 -> 3700 | ... BS17: =+BR17+BS32 -> 14000
S18: TT | T18: SL Lũy kế giấy sóng-TT | U18: Tấn | V18: =V33 -> 34509.206 | W18: =W33 -> 35531.191 | X18: =X33 -> 25275.764 | Y18: =Y33 -> 11767.882 | Z18: =Z33 -> 15186.893 | AA18: =AA33 -> 5053.334 | AB18: =+AB33 -> 1002.502 | AC18: =+AC33 -> 722.141 | AD18: =+AD33 -> 732.629 | AE18: =+AE33 -> 1654.56 | AF18: =+AF33 -> 941.502 | AG18: =+AG33 -> 0.0037174642 | AH18: =+AH33 -> 0.00026678314 | AI18: =+AI33 -> 0 | ... AM18: =+AM33 -> 0 | AO18: =+AN18+AO33 -> 225.113 | AP18: =+AO18+AP33 -> 295.441 | AQ18: =+AP18+AQ33 -> 304.965 | AR18: =+AQ18+AR33 -> 304.965 | AS18: =+AR18+AS33 -> 304.965 | AT18: =+AS18+AT33 -> 304.965 | AU18: =+AT18+AU33 -> 304.965 | AV18: =+AU18+AV33 -> 304.965 | ... BS18: =+BR18+BS33 -> 941.502
T19: SL Lũy kế giấy mặt-TT | U19: Tấn | V19: =V34 -> 31552.498 | W19: =W34 -> 82586.796 | X19: =X34 -> 90749.445 | Y19: =Y34 -> 90236.048 | Z19: =Z34 -> 113789.6 | AA19: =AA34 -> 51853.368 | AB19: =+AB34 -> 10011.423 | AC19: =+AC34 -> 9960.315 | AD19: =+AD34 -> 11050.316 | AE19: =+AE34 -> 9685.954 | AF19: =+AF34 -> 11145.36 | AG19: =+AG34 -> 0.015950584 | AH19: =+AH34 -> 0.013550678 | AI19: =+AI34 -> 0 | ... AM19: =+AM34 -> 0 | AO19: =+AN19+AO34 -> 87.175 | AP19: =+AO19+AP34 -> 420.776 | AQ19: =+AP19+AQ34 -> 820.68 | AR19: =+AQ19+AR34 -> 1272.806 | AS19: =+AR19+AS34 -> 1780.331 | AT19: =+AS19+AT34 -> 2296.758 | AU19: =+AT19+AU34 -> 2787.863 | AV19: =+AU19+AV34 -> 3223.661 | ... BS19: =+BR19+BS34 -> 11145.36
T20: SL Lũy kế Kraftlinet -TT | U20: Tấn | V20: =V35 -> 0 | W20: =W35 -> 847.149 | X20: =X35 -> 7819.05 | Y20: =Y35 -> 18734.028 | Z20: =Z35 -> 19060.961 | AA20: =AA35 -> 7749.82 | AB20: =+AB35 -> 2109.274 | AC20: =+AC35 -> 1394.903 | AD20: =+AD35 -> 1528.139 | AE20: =+AE35 -> 1685.096 | AF20: =+AF35 -> 1032.408 | AG20: =+AG35 -> 0.08843403 | AH20: =+AH35 -> 0.0069592287 | AI20: =+AI35 -> 0 | ... AM20: =+AM35 -> 0 | AO20: =+AN20+AO35 -> 0 | AP20: =+AO20+AP35 -> 0 | AQ20: =+AP20+AQ35 -> 0 | AR20: =+AQ20+AR35 -> 0 | AS20: =+AR20+AS35 -> 0 | AT20: =+AS20+AT35 -> 0 | AU20: =+AT20+AU35 -> 0 | AV20: =+AU20+AV35 -> 0 | ... BS20: =+BR20+BS35 -> 1032.408
T21: SL Lũy kế Tổng -TT | U21: Tấn | V21: =SUM(V18:V20) -> 66061.704 | W21: =SUM(W18:W20) -> 118965.14 | X21: =SUM(X18:X20) -> 123844.26 | Y21: =SUM(Y18:Y20) -> 120737.96 | Z21: =SUM(Z18:Z20) -> 148037.46 | AA21: =SUM(AA18:AA20) -> 64656.522 | AB21: =SUM(AB18:AB20) -> 13123.199 | AC21: =SUM(AC18:AC20) -> 12077.359 | ... AM21: =SUM(AM18:AM20) -> 0 | AO21: =+AN21+AO36 -> 312.288 | AP21: =+AO21+AP36 -> 716.217 | AQ21: =+AP21+AQ36 -> 1125.645 | AR21: =+AQ21+AR36 -> 1577.771 | AS21: =+AR21+AS36 -> 2085.296 | AT21: =+AS21+AT36 -> 2601.723 | AU21: =+AT21+AU36 -> 3092.828 | AV21: =+AU21+AV36 -> 3528.626 | ... BS21: =+BR21+BS36 -> 13119.27
S22: Chênh lũy kế ( + , -) | U22: Tấn | V22: =V21-V17 -> -9117.9176 | W22: =W21-W17 -> -3217.0089 | X22: =X21-X17 -> -3185.1731 | Y22: =Y21-Y17 -> -6572.9609 | Z22: =Z21-Z17 -> -11362.541 | AA22: =AA21-AA17 -> -3678.478 | AB22: =AB21-AB17 -> -1076.801 | AC22: =AC21-AC17 -> -477.641 | ... AM22: =AM21-AM17 -> 0 | AO22: =AO21-AO17 -> -37.712 | AP22: =AP21-AP17 -> -53.783 | AQ22: =AQ21-AQ17 -> -124.355 | AR22: =AR21-AR17 -> -162.229 | AS22: =AS21-AS17 -> -154.704 | AT22: =AT21-AT17 -> -158.277 | AU22: =AU21-AU17 -> -157.172 | AV22: =AV21-AV17 -> -171.374 | ... BS22: =BS21-BS17 -> -880.73
R23: TỶ LỆ ĐẠT SẢN LƯỢNG MỤC TIÊU | T23: Muc tiêu TỶ LỆ | U23: % | V23: 0.95 | W23: 0.95 | X23: 0.95 | Y23: 0.95 | Z23: 0.95 | AA23: 0.95 | AB23: 0.95 | AC23: 0.95 | AD23: 0.95 | AE23: 0.95 | AF23: 0.95 | AG23: 0.95 | AH23: 0.95 | AI23: 0.95 | AJ23: 0.95 | AK23: 0.95 | AL23: 0.95 | AM23: 0.95 | AO23: 0.95 | AP23: 0.95 | AQ23: 0.95 | AR23: 0.95 | AS23: 0.95 | AT23: 0.95 | AU23: 0.95 | AV23: 0.95 | AW23: 0.95 | AX23: 0.95 | AY23: 0.95 | AZ23: 0.95 | BA23: 0.95 | BB23: 0.95 | BC23: 0.95 | BD23: 0.95 | BE23: 0.95 | BF23: 0.95 | BG23: 0.95 | BH23: 0.95 | BI23: 0.95 | BJ23: 0.95 | BK23: 0.95 | BL23: 0.95 | BM23: 0.95 | BN23: 0.95 | BO23: 0.95 | BP23: 0.95 | BQ23: 0.95 | BR23: 0.95 | BS23: 0.95
T24: Muc tiêu TỶ LỆ | U24: % | V24: 0.85 | W24: 0.85 | X24: 0.85 | Y24: 0.85 | Z24: 0.85 | AA24: 0.85 | AB24: 0.85 | AC24: 0.85 | AD24: 0.85 | AE24: 0.85 | AF24: 0.85 | AG24: 0.85 | AH24: 0.85 | AI24: 0.85 | AJ24: 0.85 | AK24: 0.85 | AL24: 0.85 | AM24: 0.85 | AO24: 0.85 | AP24: 0.85 | AQ24: 0.85 | AR24: 0.85 | AS24: 0.85 | AT24: 0.85 | AU24: 0.85 | AV24: 0.85 | AW24: 0.85 | AX24: 0.85 | AY24: 0.85 | AZ24: 0.85 | BA24: 0.85 | BB24: 0.85 | BC24: 0.85 | BD24: 0.85 | BE24: 0.85 | BF24: 0.85 | BG24: 0.85 | BH24: 0.85 | BI24: 0.85 | BJ24: 0.85 | BK24: 0.85 | BL24: 0.85 | BM24: 0.85 | BN24: 0.85 | BO24: 0.85 | BP24: 0.85 | BQ24: 0.85 | BR24: 0.85 | BS24: 0.85
R25: Số ngày sản xuất | T25: Tổng Số ngày đã SX | U25: Ngày | V25: ='Data NĂM'!F4 -> 225 | W25: ='Data NĂM'!G4 -> 342 | X25: ='Data NĂM'!H4 -> 356 | Y25: ='Data NĂM'!I4 -> 326 | Z25: ='Data NĂM'!J4 -> 492 | AA25: ='Data NĂM'!K4 -> 0 | AB25: =+'Data NĂM'!BP4 -> 30 | AC25: =+'Data NĂM'!BT4 -> 30 | AD25: =+'Data NĂM'!BU4 -> 0 | AE25: =+'Data NĂM'!BV4 -> 0 | AF25: =+'Data NĂM'!BW4 -> 0 | AG25: =+'Data NĂM'!BY4 -> 0 | AH25: =+'Data NĂM'!BZ4 -> 0 | AI25: =+'Data NĂM'!CA4 -> 0 | AJ25: =+'Data NĂM'!CB4 -> 0 | AK25: =+'Data NĂM'!CC4 -> 0 | AL25: =+'Data NĂM'!CD4 -> 0 | AM25: =+'Data NĂM'!CE4 -> 0 | AO25: ='5.26'!G4 -> 1 | AP25: ='5.26'!H4 -> 1 | AQ25: ='5.26'!I4 -> 1 | AR25: ='5.26'!J4 -> 1 | AS25: ='5.26'!K4 -> 1 | AT25: ='5.26'!L4 -> 1 | AU25: ='5.26'!M4 -> 1 | AV25: ='5.26'!N4 -> 1 | ... BT25: ='5.26'!AL4 -> 0
T26: Tổng Số ngày sx giấy mặt | U26: Ngày | V26: ='Data NĂM'!F5 -> 118 | W26: ='Data NĂM'!G5 -> 311 | X26: ='Data NĂM'!H5 -> 324 | Y26: ='Data NĂM'!I5 -> 318 | Z26: ='Data NĂM'!J5 -> 487 | AA26: ='Data NĂM'!K5 -> 0 | AB26: =+'Data NĂM'!BP5 -> 30 | AC26: =+'Data NĂM'!BT5 -> 30 | AD26: =+'Data NĂM'!BU5 -> 0 | AE26: =+'Data NĂM'!BV5 -> 0 | AF26: =+'Data NĂM'!BW5 -> 0 | AG26: =+'Data NĂM'!BY5 -> 0 | AH26: =+'Data NĂM'!BZ5 -> 0 | AI26: =+'Data NĂM'!CA5 -> 0 | AJ26: =+'Data NĂM'!CB5 -> 0 | AK26: =+'Data NĂM'!CC5 -> 0 | AL26: =+'Data NĂM'!CD5 -> 0 | AM26: =+'Data NĂM'!CE5 -> 0 | AO26: ='5.26'!G5 -> 1 | AP26: ='5.26'!H5 -> 1 | AQ26: ='5.26'!I5 -> 1 | AR26: ='5.26'!J5 -> 1 | AS26: ='5.26'!K5 -> 1 | AT26: ='5.26'!L5 -> 1 | AU26: ='5.26'!M5 -> 1 | AV26: ='5.26'!N5 -> 1 | ... BT26: ='5.26'!AL5 -> 0
T27: Tổng số ngày SX Kraftlinet | V27: ='Data NĂM'!F6 -> 0 | W27: ='Data NĂM'!G6 -> 8 | X27: ='Data NĂM'!H6 -> 36 | Y27: ='Data NĂM'!I6 -> 79 | Z27: ='Data NĂM'!J6 -> 92 | AA27: ='Data NĂM'!K6 -> 0 | AB27: =+'Data NĂM'!BP6 -> 7 | AC27: =+'Data NĂM'!BT6 -> 3 | AD27: =+'Data NĂM'!BU6 -> 0 | AE27: =+'Data NĂM'!BV6 -> 0 | AF27: =+'Data NĂM'!BW6 -> 0 | AG27: =+'Data NĂM'!BY6 -> 0 | AH27: =+'Data NĂM'!BZ6 -> 0 | AI27: =+'Data NĂM'!CA6 -> 0 | AJ27: =+'Data NĂM'!CB6 -> 0 | AK27: =+'Data NĂM'!CC6 -> 0 | AL27: =+'Data NĂM'!CD6 -> 0 | AM27: =+'Data NĂM'!CE6 -> 0 | AO27: ='5.26'!G6 -> 0 | AP27: ='5.26'!H6 -> 0 | AQ27: ='5.26'!I6 -> 0 | AR27: ='5.26'!J6 -> 0 | AS27: ='5.26'!K6 -> 0 | AT27: ='5.26'!L6 -> 0 | AU27: ='5.26'!M6 -> 0 | AV27: ='5.26'!N6 -> 0 | ... BT27: ='5.26'!AL6 -> 0
R28: KẾ HOẠCH NS | T28: SẢN LƯƠNG KH NGẤN SÁCH | U28: TẤN | V28: 75179.622 | W28: 122182.15 | X28: 127666 | Y28: 136881 | Z28: =+Z32 -> 159400 | AA28: =+SUM(AB28:AN28) -> 68335 | AB28: 14200 | AC28: 12555 | AD28: 14000 | AE28: 13580 | AF28: 14000
R29: KẾ HOẠCH | S29: Sản lượng KH | T29: Giấy sóng-KH | U29: Tấn | V29: ='Data NĂM'!F7 -> 40397.894 | W29: ='Data NĂM'!G7 -> 37100.1 | X29: ='Data NĂM'!H7 -> 26535.138 | Y29: ='Data NĂM'!I7 -> 12464.328 | Z29: ='Data NĂM'!J7 -> 16779 | AA29: ='Data NĂM'!K7 -> 5403 | AB29: =+'Data NĂM'!BP7 -> 1213 | AC29: =+'Data NĂM'!BQ7 -> 760 | AD29: =+'Data NĂM'!BR7 -> 770 | AE29: =+'Data NĂM'!BS7 -> 1620 | AF29: =+'Data NĂM'!BT7 -> 1040 | AG29: =+'Data NĂM'!BY7 -> 0 | AH29: =+'Data NĂM'!BZ7 -> 0 | AI29: =+'Data NĂM'!CA7 -> 0 | AJ29: =+'Data NĂM'!CB7 -> 0 | AK29: =+'Data NĂM'!CC7 -> 0 | AL29: =+'Data NĂM'!CD7 -> 0 | AM29: =+'Data NĂM'!CE7 -> 0 | AO29: ='5.26'!G7 -> 250 | AP29: ='5.26'!H7 -> 70 | AQ29: ='5.26'!I7 -> 10 | AR29: ='5.26'!J7 -> 0 | AS29: ='5.26'!K7 -> 0 | AT29: ='5.26'!L7 -> 0 | AU29: ='5.26'!M7 -> 0 | AV29: ='5.26'!N7 -> 0 | ... BT29: ='5.26'!AL7 -> 0
T30: Giấy mặt-KH | U30: Tấn | V30: ='Data NĂM'!F8 -> 34781.727 | W30: ='Data NĂM'!G8 -> 84192.395 | X30: ='Data NĂM'!H8 -> 92552.526 | Y30: ='Data NĂM'!I8 -> 95041.54 | Z30: ='Data NĂM'!J8 -> 121993 | AA30: ='Data NĂM'!K8 -> 54940 | AB30: =+'Data NĂM'!BP8 -> 10800 | AC30: =+'Data NĂM'!BQ8 -> 10350 | AD30: =+'Data NĂM'!BR8 -> 11685 | AE30: =+'Data NĂM'!BS8 -> 10270 | AF30: =+'Data NĂM'!BT8 -> 11835 | AG30: =+'Data NĂM'!BY8 -> 0 | AH30: =+'Data NĂM'!BZ8 -> 0 | AI30: =+'Data NĂM'!CA8 -> 0 | AJ30: =+'Data NĂM'!CB8 -> 0 | AK30: =+'Data NĂM'!CC8 -> 0 | AL30: =+'Data NĂM'!CD8 -> 0 | AM30: =+'Data NĂM'!CE8 -> 0 | AO30: ='5.26'!G8 -> 100 | AP30: ='5.26'!H8 -> 350 | AQ30: ='5.26'!I8 -> 470 | AR30: ='5.26'!J8 -> 490 | AS30: ='5.26'!K8 -> 500 | AT30: ='5.26'!L8 -> 520 | AU30: ='5.26'!M8 -> 490 | AV30: ='5.26'!N8 -> 450 | ... BT30: ='5.26'!AL8 -> 0
T31: Kraftlinet-KH | U31: Tấn | V31: ='Data NĂM'!F9 -> 0 | W31: ='Data NĂM'!G9 -> 889.64976 | X31: ='Data NĂM'!H9 -> 7941.7685 | Y31: ='Data NĂM'!I9 -> 19805.051 | Z31: ='Data NĂM'!J9 -> 20628 | AA31: ='Data NĂM'!K9 -> 7992 | AB31: =+'Data NĂM'!BP9 -> 2187 | AC31: =+'Data NĂM'!BQ9 -> 1445 | AD31: =+'Data NĂM'!BR9 -> 1545 | AE31: =+'Data NĂM'!BS9 -> 1690 | AF31: =+'Data NĂM'!BT9 -> 1125 | AG31: =+'Data NĂM'!BY9 -> 0 | AH31: =+'Data NĂM'!BZ9 -> 0 | AI31: =+'Data NĂM'!CA9 -> 0 | AJ31: =+'Data NĂM'!CB9 -> 0 | AK31: =+'Data NĂM'!CC9 -> 0 | AL31: =+'Data NĂM'!CD9 -> 0 | AM31: =+'Data NĂM'!CE9 -> 0 | AO31: ='5.26'!G9 -> 0 | AP31: ='5.26'!H9 -> 0 | AQ31: ='5.26'!I9 -> 0 | AR31: ='5.26'!J9 -> 0 | AS31: ='5.26'!K9 -> 0 | AT31: ='5.26'!L9 -> 0 | AU31: ='5.26'!M9 -> 0 | AV31: ='5.26'!N9 -> 0 | ... BT31: ='5.26'!AL9 -> 0
T32: TỔNG SL KẾ HOẠCH | U32: Tấn | V32: =SUM(V29:V31) -> 75179.622 | W32: =SUM(W29:W31) -> 122182.15 | X32: =SUM(X29:X31) -> 127029.43 | Y32: =SUM(Y29:Y31) -> 127310.92 | Z32: =SUM(Z29:Z31) -> 159400 | AA32: =SUM(AA29:AA31) -> 68335 | AB32: =+SUM(AB29:AB31) -> 14200 | AC32: =+SUM(AC29:AC31) -> 12555 | AD32: =+SUM(AD29:AD31) -> 14000 | AE32: =+SUM(AE29:AE31) -> 13580 | AF32: =+SUM(AF29:AF31) -> 14000 | AG32: =+SUM(AG29:AG31) -> 0 | AH32: =+SUM(AH29:AH31) -> 0 | AI32: =+SUM(AI29:AI31) -> 0 | ... AM32: =+SUM(AM29:AM31) -> 0 | AO32: =AO30+AO29+AO31 -> 350 | AP32: =AP30+AP29+AP31 -> 420 | AQ32: =AQ30+AQ29+AQ31 -> 480 | AR32: =AR30+AR29+AR31 -> 490 | AS32: =AS30+AS29+AS31 -> 500 | AT32: =AT30+AT29+AT31 -> 520 | AU32: =AU30+AU29+AU31 -> 490 | AV32: =AV30+AV29+AV31 -> 450 | ... BT32: =BT30+BT29+BT31 -> 0
R33: THỰC TẾ | S33: SL Thực tế | T33: Giấy sóng-TT | U33: Tấn | V33: ='Data NĂM'!F11 -> 34509.206 | W33: ='Data NĂM'!G11 -> 35531.191 | X33: ='Data NĂM'!H11 -> 25275.764 | Y33: ='Data NĂM'!I11 -> 11767.882 | Z33: ='Data NĂM'!J11 -> 15186.893 | AA33: ='Data NĂM'!K11 -> 5053.334 | AB33: =+'Data NĂM'!BP11 -> 1002.502 | AC33: =+'Data NĂM'!BQ11 -> 722.141 | AD33: =+'Data NĂM'!BR11 -> 732.629 | AE33: =+'Data NĂM'!BS11 -> 1654.56 | AF33: =+'Data NĂM'!BT11 -> 941.502 | AG33: =+'Data NĂM'!BY11 -> 0.0037174642 | AH33: =+'Data NĂM'!BZ11 -> 0.00026678314 | AI33: =+'Data NĂM'!CA11 -> 0 | AJ33: =+'Data NĂM'!CB11 -> 0 | AK33: =+'Data NĂM'!CC11 -> 0 | AL33: =+'Data NĂM'!CD11 -> 0 | AM33: =+'Data NĂM'!CE11 -> 0 | AO33: ='5.26'!G11 -> 225.113 | AP33: ='5.26'!H11 -> 70.328 | AQ33: ='5.26'!I11 -> 9.524 | AR33: ='5.26'!J11 -> 0 | AS33: ='5.26'!K11 -> 0 | AT33: ='5.26'!L11 -> 0 | AU33: ='5.26'!M11 -> 0 | AV33: ='5.26'!N11 -> 0 | ... BT33: ='5.26'!AL11 -> 0
T34: Giấy mặt-TT | U34: Tấn | V34: ='Data NĂM'!F12 -> 31552.498 | W34: ='Data NĂM'!G12 -> 82586.796 | X34: ='Data NĂM'!H12 -> 90749.445 | Y34: ='Data NĂM'!I12 -> 90236.048 | Z34: ='Data NĂM'!J12 -> 113789.6 | AA34: ='Data NĂM'!K12 -> 51853.368 | AB34: =+'Data NĂM'!BP12 -> 10011.423 | AC34: =+'Data NĂM'!BQ12 -> 9960.315 | AD34: =+'Data NĂM'!BR12 -> 11050.316 | AE34: =+'Data NĂM'!BS12 -> 9685.954 | AF34: =+'Data NĂM'!BT12 -> 11145.36 | AG34: =+'Data NĂM'!BY12 -> 0.015950584 | AH34: =+'Data NĂM'!BZ12 -> 0.013550678 | AI34: =+'Data NĂM'!CA12 -> 0 | AJ34: =+'Data NĂM'!CB12 -> 0 | AK34: =+'Data NĂM'!CC12 -> 0 | AL34: =+'Data NĂM'!CD12 -> 0 | AM34: =+'Data NĂM'!CE12 -> 0 | AO34: ='5.26'!G12 -> 87.175 | AP34: ='5.26'!H12 -> 333.601 | AQ34: ='5.26'!I12 -> 399.904 | AR34: ='5.26'!J12 -> 452.126 | AS34: ='5.26'!K12 -> 507.525 | AT34: ='5.26'!L12 -> 516.427 | AU34: ='5.26'!M12 -> 491.105 | AV34: ='5.26'!N12 -> 435.798 | ... BT34: ='5.26'!AL12 -> 0
T35: Kraftlinet-TT | U35: Tấn | V35: ='Data NĂM'!F13 -> 0 | W35: ='Data NĂM'!G13 -> 847.149 | X35: ='Data NĂM'!H13 -> 7819.05 | Y35: ='Data NĂM'!I13 -> 18734.028 | Z35: ='Data NĂM'!J13 -> 19060.961 | AA35: ='Data NĂM'!K13 -> 7749.82 | AB35: =+'Data NĂM'!BP13 -> 2109.274 | AC35: =+'Data NĂM'!BQ13 -> 1394.903 | AD35: =+'Data NĂM'!BR13 -> 1528.139 | AE35: =+'Data NĂM'!BS13 -> 1685.096 | AF35: =+'Data NĂM'!BT13 -> 1032.408 | AG35: =+'Data NĂM'!BY13 -> 0.08843403 | AH35: =+'Data NĂM'!BZ13 -> 0.0069592287 | AI35: =+'Data NĂM'!CA13 -> 0 | AJ35: =+'Data NĂM'!CB13 -> 0 | AK35: =+'Data NĂM'!CC13 -> 0 | AL35: =+'Data NĂM'!CD13 -> 0 | AM35: =+'Data NĂM'!CE13 -> 0 | AO35: ='5.26'!G13 -> 0 | AP35: ='5.26'!H13 -> 0 | AQ35: ='5.26'!I13 -> 0 | AR35: ='5.26'!J13 -> 0 | AS35: ='5.26'!K13 -> 0 | AT35: ='5.26'!L13 -> 0 | AU35: ='5.26'!M13 -> 0 | AV35: ='5.26'!N13 -> 0 | ... BT35: ='5.26'!AL13 -> 0
T36: TỔNG SL THƯC TẾ | U36: Tấn | V36: =SUM(V33:V35) -> 66061.704 | W36: =SUM(W33:W35) -> 118965.14 | X36: =SUM(X33:X35) -> 123844.26 | Y36: =SUM(Y33:Y35) -> 120737.96 | Z36: =SUM(Z33:Z35) -> 148037.46 | AA36: =SUM(AA33:AA35) -> 64656.522 | AB36: =SUM(AB33:AB35) -> 13123.199 | AC36: =SUM(AC33:AC35) -> 12077.359 | ... AM36: =SUM(AM33:AM35) -> 0 | AO36: =AO33+AO34+AO35 -> 312.288 | AP36: =AP33+AP34+AP35 -> 403.929 | AQ36: =AQ33+AQ34+AQ35 -> 409.428 | AR36: =AR33+AR34+AR35 -> 452.126 | AS36: =AS33+AS34+AS35 -> 507.525 | AT36: =AT33+AT34+AT35 -> 516.427 | AU36: =AU33+AU34+AU35 -> 491.105 | AV36: =AV33+AV34+AV35 -> 435.798 | ... BT36: =BT33+BT34+BT35 -> 0
